Workbook

Sheet Sheet1
E1: OU
B2: Year | C2: Year | D2: Month | E2: HDAN | F2: PPAN | G2: Natural gas | I2: URALS Crude Oil | J2: Аммиак | L2: Азотын хүчил | N2: Аммиак | O2: Азотын хүчил | P2: PPAN | Q2: HDAN | X2: Азот (Бласт ХХК) | Y2: Азот (Очир-Ундраа Групп) | Z2: Азот (Спейшлмайнинг сервис) | AA2: Уралхим (Спейшлмайнинг Сервис ХХК) | AB2: Уралхим (Бест вестерн тех ХХК)
A3: 44774 | B3: 2022-08 | C3: 2022 | D3: 8 | E3: 500 | F3: 550 | G3: 3.4 | I3: 69.7 | J3: 915 | L3: 652 | M3: 567 | N3: 458 | O3: 326 | P3: 500 | Q3: 550
A4: 44805 | B4: 2022-09 | C4: 2022 | D4: 9 | E4: 500 | F4: 530 | G4: 3.6 | I4: 75.7 | J4: 1076 | L4: 904 | M4: 752 | N4: 538 | O4: 452 | P4: 500 | Q4: 530 | R4: 0.07 | S4: 0.09 | T4: 0.18 | U4: 0.38 | V4: 0 | W4: -0.04
A5: 44835 | B5: 2022-10 | C5: 2022 | D5: 10 | E5: 500 | F5: 530 | G5: 3.7 | I5: 82.1 | J5: 885 | L5: 974 | M5: 764 | N5: 443 | O5: 487 | P5: 500 | Q5: 530 | R5: 0.03 | S5: 0.08 | T5: -0.18 | U5: 0.08 | V5: 0 | W5: 0
A6: 44866 | B6: 2022-11 | C6: 2022 | D6: 11 | E6: 500 | F6: 550 | G6: 3.6 | I6: 70.8 | J6: 772 | L6: 821 | M6: 648 | N6: 386 | O6: 410 | P6: 500 | Q6: 550 | R6: -0.04 | S6: -0.14 | T6: -0.13 | U6: -0.16 | V6: 0 | W6: 0.04
A7: 44896 | B7: 2022-12 | C7: 2022 | D7: 12 | E7: 500 | F7: 540 | G7: 3.5 | I7: 73.6 | J7: 518 | L7: 936 | M7: 678 | N7: 259 | O7: 468 | P7: 500 | Q7: 540 | R7: -0.02 | S7: 0.04 | T7: -0.33 | U7: 0.14 | V7: 0 | W7: -0.02
A8: 44927 | B8: 2023-01 | C8: 2023 | D8: 1 | E8: 500 | F8: 550 | G8: 3.3 | I8: 96.2 | J8: 915 | L8: 779 | M8: 646 | N8: 458 | O8: 389 | P8: 500 | Q8: 550 | R8: -0.06 | S8: 0.31 | T8: 0.77 | U8: -0.17 | V8: 0 | W8: 0.02
A9: 44958 | B9: 2023-02 | C9: 2023 | D9: 2 | F9: 540 | G9: 3.3 | I9: 94.3 | J9: 633 | L9: 849 | M9: 642 | N9: 316 | O9: 424 | P9: 500 | Q9: 540 | R9: 0.01 | S9: -0.02 | T9: -0.31 | U9: 0.09 | V9: 0 | W9: -0.02
A10: 44986 | B10: 2023-03 | C10: 2023 | D10: 3 | E10: 460 | F10: 550 | G10: 3.4 | I10: 81.9 | J10: 553 | L10: 551 | M10: 441 | N10: 276 | O10: 276 | P10: 460 | Q10: 550 | R10: 0.04 | S10: -0.13 | T10: -0.13 | U10: -0.35 | V10: -0.08 | W10: 0.02
A11: 45017 | B11: 2023-04 | C11: 2023 | D11: 4 | F11: 550 | G11: 3.5 | I11: 79.4 | J11: 364 | L11: 588 | M11: 432 | N11: 182 | O11: 294 | P11: 460 | Q11: 550 | R11: 0.02 | S11: -0.03 | T11: -0.34 | U11: 0.07 | V11: 0 | W11: 0
A12: 45047 | B12: 2023-05 | C12: 2023 | D12: 5 | E12: 460 | F12: 330 | G12: 3.6 | I12: 90.7 | J12: 356 | L12: 537 | M12: 399 | N12: 178 | O12: 268 | P12: 460 | Q12: 330 | R12: 0.01 | S12: 0.14 | T12: -0.02 | U12: -0.09 | V12: 0 | W12: -0.4
A13: 45078 | B13: 2023-06 | C13: 2023 | D13: 6 | E13: 300 | F13: 330 | G13: 3.6 | I13: 89.7 | J13: 257 | L13: 477 | M13: 344 | N13: 129 | O13: 239 | P13: 300 | Q13: 330 | R13: 0.01 | S13: -0.01 | T13: -0.28 | U13: -0.11 | V13: -0.35 | W13: 0
A14: 45108 | B14: 2023-07 | C14: 2023 | D14: 7 | E14: 300 | F14: 330 | G14: 3.5 | I14: 82.8 | J14: 252 | L14: 355 | M14: 266 | N14: 126 | O14: 177 | P14: 300 | Q14: 330 | R14: -0.04 | S14: -0.08 | T14: -0.02 | U14: -0.26 | V14: 0 | W14: 0
A15: 45139 | B15: 2023-08 | C15: 2023 | D15: 8 | E15: 250 | F15: 280 | G15: 3.4 | I15: 79.8 | J15: 245 | L15: 448 | M15: 324 | N15: 122 | O15: 224 | P15: 250 | Q15: 280 | R15: -0.01 | S15: -0.04 | T15: -0.03 | U15: 0.26 | V15: -0.17 | W15: -0.15
A16: 45170 | B16: 2023-09 | C16: 2023 | D16: 9 | E16: 250 | F16: 280 | G16: 3.4 | I16: 72.2 | J16: 274 | L16: 451 | M16: 331 | N16: 137 | O16: 225 | P16: 250 | Q16: 280 | R16: -0.02 | S16: -0.1 | T16: 0.12 | U16: 0.01 | V16: 0 | W16: 0
A17: 45200 | B17: 2023-10 | C17: 2023 | D17: 10 | E17: 250 | F17: 280 | G17: 3.3 | I17: 80 | J17: 371 | L17: 377 | M17: 301 | N17: 185 | O17: 188 | P17: 250 | Q17: 280 | R17: -0.01 | S17: 0.11 | T17: 0.35 | U17: -0.16 | V17: 0 | W17: 0
A18: 45231 | B18: 2023-11 | C18: 2023 | D18: 11 | E18: 300 | F18: 280 | G18: 3.3 | I18: 63.7 | J18: 392 | L18: 507 | M18: 386 | N18: 196 | O18: 253 | P18: 300 | Q18: 280 | R18: -0.02 | S18: -0.2 | T18: 0.06 | U18: 0.34 | V18: 0.2 | W18: 0
A19: 45261 | B19: 2023-12 | C19: 2023 | D19: 12 | E19: 300 | F19: 330 | G19: 3.2 | I19: 57.3 | J19: 424 | L19: 581 | M19: 438 | N19: 212 | O19: 290 | P19: 300 | Q19: 330 | R19: -0.03 | S19: -0.1 | T19: 0.08 | U19: 0.15 | V19: 0 | W19: 0.18
A20: 45292 | B20: 2024-01 | C20: 2024 | D20: 1 | E20: 310 | F20: 330 | G20: 3 | I20: 71.5 | J20: 373 | L20: 464 | M20: 356 | N20: 186 | O20: 232 | P20: 310 | Q20: 330 | R20: -0.06 | S20: 0.25 | T20: -0.12 | U20: -0.2 | V20: 0.03 | W20: 0 | X20: #DIV/0! | Y20: 330 | Z20: #DIV/0! | AA20: 308.33333 | AB20: 315
A21: 45323 | B21: 2024-02 | C21: 2024 | D21: 2 | E21: 310 | F21: 330 | G21: 3 | I21: 74.6 | J21: 417 | L21: 442 | M21: 349 | N21: 208 | O21: 221 | P21: 310 | Q21: 330 | R21: 0.02 | S21: 0.04 | T21: 0.12 | U21: -0.05 | V21: 0 | W21: 0 | X21: 330 | Y21: 330 | Z21: #DIV/0! | AA21: 305 | AB21: 285
A22: 45352 | B22: 2024-03 | C22: 2024 | D22: 3 | E22: 300 | F22: 330 | G22: 2.9 | I22: 77.3 | J22: 381 | L22: 456 | M22: 352 | N22: 191 | O22: 228 | P22: 300 | Q22: 330 | R22: -0.04 | S22: 0.04 | T22: -0.09 | U22: 0.03 | V22: -0.03 | W22: 0 | X22: 330 | Y22: 330 | Z22: #DIV/0! | AA22: 305 | AB22: 286.875
A23: 45383 | B23: 2024-04 | C23: 2024 | D23: 4 | E23: 300 | F23: 330 | G23: 2.7 | I23: 75.2 | J23: 371 | L23: 551 | M23: 410 | N23: 185 | O23: 276 | P23: 300 | Q23: 330 | R23: -0.05 | S23: -0.03 | T23: -0.03 | U23: 0.21 | V23: 0 | W23: 0 | X23: 330 | Y23: 330 | Z23: #DIV/0! | AA23: 313.625 | AB23: 297.5
A24: 45413 | B24: 2024-05 | C24: 2024 | D24: 5 | E24: 260 | F24: 300 | G24: 2.7 | I24: 70.9 | J24: 362 | L24: 514 | M24: 385 | N24: 181 | O24: 257 | P24: 260 | Q24: 300 | R24: -0.03 | S24: -0.06 | T24: -0.02 | U24: -0.07 | V24: -0.13 | W24: -0.09 | X24: 319 | Y24: 230 | Z24: #DIV/0! | AA24: #DIV/0! | AB24: #DIV/0!
A25: 45444 | B25: 2024-06 | C25: 2024 | D25: 6 | E25: 230 | F25: 270 | G25: 2.6 | I25: 80 | J25: 337 | L25: 630 | M25: 454 | N25: 169 | O25: 315 | P25: 230 | Q25: 270 | R25: -0.01 | S25: 0.13 | T25: -0.07 | U25: 0.23 | V25: -0.12 | W25: -0.1 | X25: #DIV/0! | Y25: #DIV/0! | Z25: #DIV/0! | AA25: 296.2 | AB25: 260
A26: 45474 | B26: 2024-07 | C26: 2024 | D26: 7 | E26: 258 | F26: 272 | G26: 2.7 | I26: 75.7 | J26: 377 | L26: 664 | M26: 482 | N26: 188 | O26: 332 | P26: 258 | Q26: 272 | R26: 0.03 | S26: -0.05 | T26: 0.12 | U26: 0.05 | V26: 0.12 | W26: 0.01 | X26: #DIV/0! | Y26: #DIV/0! | Z26: #DIV/0! | AA26: 295 | AB26: 260
A27: 45505 | B27: 2024-08 | C27: 2024 | D27: 8 | E27: 250 | F27: 277 | G27: 3 | I27: 75 | J27: 403 | L27: 698 | M27: 508 | N27: 202 | O27: 349 | P27: 250 | Q27: 277 | R27: 0.11 | S27: -0.01 | T27: 0.07 | U27: 0.05 | V27: -0.03 | W27: 0.02 | X27: #DIV/0! | Y27: #DIV/0! | Z27: #DIV/0! | AA27: 334.54545 | AB27: 270
A28: 45536 | B28: 2024-09 | C28: 2024 | D28: 9 | E28: 229 | F28: 252 | G28: 3.4 | I28: 72.5 | J28: 401 | L28: 534 | M28: 405 | N28: 200 | O28: 267 | P28: 229 | Q28: 252 | R28: 0.12 | S28: -0.03 | T28: -0.01 | U28: -0.23 | V28: -0.09 | W28: -0.09 | X28: #DIV/0! | Y28: #DIV/0! | Z28: #DIV/0! | AA28: 366.25 | AB28: 270
A29: 45566 | B29: 2024-10 | C29: 2024 | D29: 10 | E29: 259 | F29: 265 | G29: 3.6 | I29: 68.6 | J29: 426 | L29: 469 | M29: 368 | N29: 213 | O29: 234 | P29: 259 | Q29: 270 | R29: 0.05 | S29: -0.05 | T29: 0.06 | U29: -0.12 | V29: 0.13 | W29: 0.07 | X29: #DIV/0! | Y29: #DIV/0! | Z29: #DIV/0! | AA29: 329.89474 | AB29: 330
A30: 45597 | B30: 2024-11 | C30: 2024 | D30: 11 | E30: 265 | F30: 270 | G30: 2.8 | I30: 69.2 | J30: 427 | L30: 416 | M30: 335 | N30: 214 | O30: 208 | P30: 265 | Q30: 270 | R30: -0.22 | S30: 0.01 | T30: 0 | U30: -0.11 | V30: 0.02 | W30: 0 | X30: #DIV/0! | Y30: #DIV/0! | Z30: #DIV/0! | AA30: 350 | AB30: 330
A31: 45627 | B31: 2024-12 | C31: 2024 | D31: 12 | E31: 244 | F31: 264 | G31: 2.4 | I31: 70.4 | J31: 454 | L31: 479 | M31: 379 | N31: 227 | O31: 239 | P31: 244 | Q31: 270 | R31: -0.15 | S31: 0.02 | T31: 0.06 | U31: 0.15 | V31: -0.08 | W31: 0 | X31: 328 | Y31: 335 | Z31: 342 | AA31: 295.82609 | AB31: 257
A32: 45658 | B32: 2025-01 | C32: 2025 | D32: 1 | G32: 3.9 | I32: 71.6 | J32: 445 | L32: 518 | M32: 402 | N32: 222 | O32: 259 | P32: 276 | Q32: 301 | R32: 0.65 | S32: 0.02 | T32: -0.02 | U32: 0.08 | V32: 0.13 | W32: 0.12 | X32: 238 | Y32: #DIV/0! | Z32: 282 | AA32: #DIV/0! | AB32: #DIV/0!
A33: 45689 | B33: 2025-02 | C33: 2025 | D33: 2 | E33: 308 | F33: 309 | G33: 4.1 | I33: 67 | J33: 471 | L33: 586 | M33: 449 | N33: 235 | O33: 293 | P33: 308 | Q33: 310 | R33: 0.05 | S33: -0.06 | T33: 0.06 | U33: 0.13 | V33: 0.12 | W33: 0.03 | X33: #DIV/0! | Y33: 319 | Z33: 304 | AA33: 310 | AB33: #DIV/0!
A34: 45717 | B34: 2025-03 | C34: 2025 | D34: 3 | E34: 301 | F34: 311 | G34: 3.8 | I34: 66.5 | J34: 445 | L34: 350 | M34: 296 | N34: 222 | O34: 175 | P34: 301 | Q34: 311 | R34: -0.07 | S34: -0.01 | T34: -0.06 | U34: -0.4 | V34: -0.02 | W34: 0 | X34: 335 | Y34: 321 | Z34: 327 | AA34: 318 | AB34: #DIV/0!
A35: 45748 | B35: 2025-04 | C35: 2025 | D35: 4 | E35: 295 | F35: 299 | G35: 3.1 | I35: 55 | J35: 275 | L35: 409 | M35: 305 | N35: 137 | O35: 205 | P35: 305 | Q35: 315 | R35: -0.18 | S35: -0.17 | T35: -0.38 | U35: 0.17 | V35: 0.01 | W35: 0.01 | X35: 320 | Y35: 320 | Z35: 327 | AA35: 290 | AB35: 320
A36: 45778 | B36: 2025-05 | C36: 2025 | D36: 5 | E36: 321 | F36: 325 | G36: 3.7 | I36: 58.7 | J36: 279 | L36: 393 | M36: 295 | N36: 140 | O36: 197 | P36: 321 | Q36: 325 | R36: 0.18 | S36: 0.07 | T36: 0.02 | U36: -0.04 | V36: 0.05 | W36: 0.03 | X36: 330 | Y36: 334 | Z36: 338 | AA36: 330 | AB36: #DIV/0!
A37: 45809 | B37: 2025-06 | C37: 2025 | D37: 6 | E37: 308 | G37: 3.9 | I37: 65.5 | J37: 299 | L37: 393 | M37: 299 | N37: 150 | O37: 197 | P37: 308 | Q37: 315 | R37: 0.05 | S37: 0.11 | T37: 0.07 | U37: 0 | V37: -0.04 | W37: -0.03 | X37: 340 | Y37: #DIV/0! | Z37: 330 | AA37: #DIV/0! | AB37: 310
A38: 45839 | B38: 2025-07 | C38: 2025 | D38: 7 | E38: 278 | F38: 306 | G38: 3.6 | I38: 65.6 | J38: 313 | L38: 402 | M38: 306 | N38: 157 | O38: 201 | P38: 308 | Q38: 320 | R38: -0.07 | S38: 0 | T38: 0.05 | U38: 0.02 | V38: 0 | W38: 0.02 | X38: #DIV/0! | Y38: 310 | Z38: 311 | AA38: 360 | AB38: 301
A39: 45870 | B39: 2025-08 | C39: 2025 | D39: 8 | G39: 3 | I39: 65.1 | J39: 325 | L39: 404 | M39: 310 | N39: 163 | O39: 202 | P39: 370 | Q39: 370 | R39: -0.17 | S39: -0.01 | T39: 0.04 | U39: 0.01 | V39: 0.2 | W39: 0.16 | X39: #DIV/0! | Y39: #DIV/0! | Z39: 300 | AA39: 361.11111 | AB39: 340
A40: 45901 | B40: 2025-09 | C40: 2025 | D40: 9 | G40: 3.3 | I40: 65.8 | J40: 324 | L40: 417 | M40: 317 | N40: 162 | O40: 208 | P40: 373 | Q40: 391 | R40: 0.13 | S40: 0.01 | T40: 0 | U40: 0.03 | V40: 0.01 | W40: 0.06 | X40: 391 | Y40: 400 | Z40: 333 | AA40: #DIV/0! | AB40: 390
...

Sheet month-unelgee
B2: date | C2: PPAN | D2: HDAN | E2: Baltic AN | F2: Ammonia | G2: Urea | H2: Natural_gas | I2: Brent | J2: PPAN | K2: AN | L2: Baltic AN | M2: Ammonia | N2: Urea | O2: Natural_gas | P2: Brent
B3: 46204 | C3: 576 | D3: 519 | E3: 417.5 | F3: 790 | G3: 406.13 | H3: 3.2 | K3: =(D3-D4)/D4 -> -0.078152753 | M3: =(F3-F4)/F4 -> -0.0125
B4: 46174 | C4: 670 | D4: 563 | E4: 500 | F4: 800 | G4: 629 | H4: 2.86 | K4: =(D4-D5)/D5 -> -0.067618369 | M4: =(F4-F5)/F5 -> 0.038961039
B5: 46143 | C5: 713.85 | D5: 603.83 | E5: 495.5 | F5: 770 | G5: 629 | H5: 2.86 | K5: =(D5-D6)/D6 -> 0.092904977 | M5: =(F5-F6)/F6 -> 0.12737921
B6: 46113 | C6: 567 | D6: 552.5 | E6: 473.25 | F6: 683 | G6: 719.38 | H6: 3.0764 | I6: 112.27 | K6: =(D6-D7)/D7 -> 0.18817204 | M6: =(F6-F7)/F7 -> 0.17253219
B7: 46082 | C7: 495 | D7: 465 | E7: 395 | F7: 582.5 | G7: 603.75 | H7: 3.05475 | I7: 102.73 | J7: =(C7-C8)/C8 -> 0.35989011 | K7: =(D7-D8)/D8 -> 0.3362069 | L7: =(E7-E8)/E8 -> 0.20380952 | M7: =(F7-F8)/F8 -> 0.18124208 | N7: =(G7-G8)/G8 -> 0.42268041 | O7: =(H7-H8)/H8 -> -0.025582545 | P7: =(I7-I8)/I8 -> 0.47606937 | R7: HDAN = 0.080991528041*HDAN(-1) + 0.303754553817*HDAN(-2) - 0.25338201366*AMMONIA(-1) + 0.269148503584*AMMONIA(-2) + 0.00378757678133*BALTIC_AN(-1) + 0.43547234846*BALTIC_AN(-2) - 12.2555082812*NATURAL_GAS(-1) + 15.7710625006*NATURAL_GAS(-2) + 0.517281394734*UREA(-1) - 0.299449478792*UREA(-2) - 3.00478655786
B8: 46054 | C8: 364 | D8: 348 | E8: 328.125 | F8: 493.125 | G8: 424.375 | H8: 3.13495 | I8: 69.597 | J8: =(C8-C9)/C9 -> 0.0083102493 | K8: =(D8-D9)/D9 -> 0.0057803468 | L8: =(E8-E9)/E9 -> 0.1697861 | M8: =(F8-F9)/F9 -> -0.051682692 | N8: =(G8-G9)/G9 -> 0.12031415 | O8: =(H8-H9)/H9 -> -0.25214282 | P8: =(I8-I9)/I9 -> 0.077451498
B9: 46023 | C9: 361 | D9: 346 | E9: 280.5 | F9: 520 | G9: 378.8 | H9: 4.19191 | I9: 64.594091 | J9: =(C9-C10)/C10 -> 0.0027777778 | K9: =(D9-D10)/D10 -> 0.054878049 | L9: =(E9-E10)/E10 -> 0.084057971 | M9: =(F9-F10)/F10 -> 0.046540881 | N9: =(G9-G10)/G10 -> 0.09400722 | O9: =(H9-H10)/H10 -> -0.053459143 | P9: =(I9-I10)/I10 -> 0.045027356
B10: 45992 | C10: 360 | D10: 328 | E10: 258.75 | F10: 496.875 | G10: 346.25 | H10: 4.4286625 | I10: 61.810909 | J10: =(C10-C11)/C11 -> 0 | K10: =(D10-D11)/D11 -> 0 | L10: =(E10-E11)/E11 -> 0.045454545 | M10: =(F10-F11)/F11 -> 0.10724234 | N10: =(G10-G11)/G11 -> -0.05846363 | O10: =(H10-H11)/H11 -> -0.010058872 | P10: =(I10-I11)/I11 -> -0.029557033
B11: 45962 | C11: 360 | D11: 328 | E11: 247.5 | F11: 448.75 | G11: 367.75 | H11: 4.4736625 | I11: 63.6935 | J11: =(C11-C12)/C12 -> -0.12408759 | K11: =(D11-D12)/D12 -> -0.12533333 | L11: =(E11-E12)/E12 -> 0.010204082 | M11: =(F11-F12)/F12 -> 0.121875 | N11: =(G11-G12)/G12 -> 0.0061559508 | O11: =(H11-H12)/H12 -> 0.33629921 | P11: =(I11-I12)/I12 -> -0.004498257
B12: 45931 | C12: 411 | D12: 375 | E12: 245 | F12: 400 | G12: 365.5 | H12: 3.3478 | I12: 63.981304 | J12: =(C12-C13)/C13 -> 0.051150895 | K12: =(D12-D13)/D13 -> 0.0053619303 | L12: =(E12-E13)/E13 -> -0.12694878 | M12: =(F12-F13)/F13 -> 0.13475177 | N12: =(G12-G13)/G13 -> -0.059504664 | O12: =(H12-H13)/H13 -> 0.1218464 | P12: =(I12-I13)/I13 -> -0.053658266
B13: 45901 | C13: 391 | D13: 373 | E13: 280.625 | F13: 352.5 | G13: 388.625 | H13: 2.9841875 | I13: 67.609091 | J13: =(C13-C14)/C14 -> 0.056756757 | K13: =(D13-D14)/D14 -> 0.0081081081 | L13: =(E13-E14)/E14 -> -0.090945902 | M13: =(F13-F14)/F14 -> 0.089644513 | N13: =(G13-G14)/G14 -> -0.12432402 | O13: =(H13-H14)/H14 -> 0.023678803 | P13: =(I13-I14)/I14 -> 0.0054250735
B14: 45870 | C14: 370 | D14: 370 | E14: 308.7 | F14: 323.5 | G14: 443.8 | H14: 2.91516 | I14: 67.244286 | J14: =(C14-C15)/C15 -> 0.15625 | K14: =(D14-D15)/D15 -> 0.2012987 | L14: =(E14-E15)/E15 -> -0.016095618 | M14: =(F14-F15)/F15 -> 0.060655738 | N14: =(G14-G15)/G15 -> 0.06235787 | O14: =(H14-H15)/H15 -> -0.13409374 | P14: =(I14-I15)/I15 -> -0.033357351
B15: 45839 | C15: 320 | D15: 308 | E15: 313.75 | F15: 305 | G15: 417.75 | H15: 3.3666 | I15: 69.564783 | J15: =(C15-C16)/C16 -> 0.015873016 | K15: =(D15-D16)/D16 -> 0 | L15: =(E15-E16)/E16 -> 0.28388747 | M15: =(F15-F16)/F16 -> 0.051724138 | N15: =(G15-G16)/G16 -> 0.092156863 | O15: =(H15-H16)/H16 -> -0.08111483 | P15: =(I15-I16)/I16 -> -0.0040357553 | S15: 3-р сар | U15: 4-р сар | W15: 4-р сар | Y15: 6-р сар | AA15: 7-р сар | AC15: 7-р сар
B16: 45809 | C16: 315 | D16: 308 | E16: 244.375 | F16: 290 | G16: 382.5 | H16: 3.6637875 | I16: 69.846667 | J16: =(C16-C17)/C17 -> -0.030769231 | K16: =(D16-D17)/D17 -> -0.040498442 | L16: =(E16-E17)/E17 -> 0.13927739 | M16: =(F16-F17)/F17 -> -0.041322314 | N16: =(G16-G17)/G17 -> 0.08974359 | O16: =(H16-H17)/H17 -> 0.065652386 | P16: =(I16-I17)/I17 -> 0.089775231 | S16: Томъёоны үнэлгээ | T16: Тооцоолсон үнэлгээ | U16: Томъёоны үнэлгээ | V16: Тооцоолсон үнэлгээ | W16: Томъёоны үнэлгээ | X16: Тооцоолсон үнэлгээ
B17: 45778 | C17: 325 | D17: 321 | E17: 214.5 | F17: 302.5 | G17: 351 | H17: 3.43807 | I17: 64.092727 | J17: =(C17-C18)/C18 -> 0.031746032 | K17: =(D17-D18)/D18 -> 0.052459016 | L17: =(E17-E18)/E18 -> -0.044011142 | M17: =(F17-F18)/F18 -> 0 | N17: =(G17-G18)/G18 -> 0.028571429 | O17: =(H17-H18)/H18 -> -0.010121717 | P17: =(I17-I18)/I18 -> -0.042352622 | R17: hdan | S17: =0.080991528041*D8 + 0.303754553817*D9 - 0.25338201366*F8 + 0.269148503584*F9 + 0.00378757678133*E8 + 0.43547234846*E9 - 12.2555082812*H8 + 15.7710625006*H9 + 0.517281394734*G8- 0.299449478792*G9 - 3.00478655786 -> 402.46065 | T17: =S17*1.15 -> 462.82974 | U17: =0.080991528041*D7 + 0.303754553817*D8 - 0.25338201366*F7 + 0.269148503584*F8 + 0.00378757678133*E7 + 0.43547234846*E8 - 12.2555082812*H7 + 15.7710625006*H8 + 0.517281394734*G7 - 0.299449478792*G8 - 3.00478655786 -> 467.1109 | V17: =U17*1.15 -> 537.17753 | W17: =0.080991528041*D6 + 0.303754553817*D7 - 0.25338201366*F6 + 0.269148503584*F7 + 0.00378757678133*E6 + 0.43547234846*E7 - 12.2555082812*H6 + 15.7710625006*H7 + 0.517281394734*G6 - 0.299449478792*G7 - 3.00478655786 -> 542.31511 | X17: =W17*1.15 -> 623.66238 | Y17: =0.080991528041*D5 + 0.303754553817*D6 - 0.25338201366*F5 + 0.269148503584*F6 + 0.00378757678133*E5 + 0.43547234846*E6 - 12.2555082812*H5 + 15.7710625006*H6 + 0.517281394734*G5 - 0.299449478792*G6 - 3.00478655786 -> 533.8324
B18: 45748 | C18: 315 | D18: 305 | E18: 224.375 | F18: 302.5 | G18: 341.25 | H18: 3.473225 | I18: 66.927273 | J18: =(C18-C19)/C19 -> 0.012861736 | K18: =(D18-D19)/D19 -> 0.013289037 | L18: =(E18-E19)/E19 -> -0.05026455 | M18: =(F18-F19)/F19 -> -0.020242915 | N18: =(G18-G19)/G19 -> -0.031914894 | O18: =(H18-H19)/H19 -> -0.16073241 | P18: =(I18-I19)/I19 -> -0.067104265
B19: 45717 | C19: 311 | D19: 301 | E19: 236.25 | F19: 308.75 | G19: 352.5 | H19: 4.1384 | I19: 71.741429 | J19: =(C19-C20)/C20 -> 0.0032258065 | K19: =(D19-D20)/D20 -> -0.022727273 | L19: =(E19-E20)/E20 -> -0.015625 | M19: =(F19-F20)/F20 -> -0.10018215 | N19: =(G19-G20)/G20 -> -0.081433225 | O19: =(H19-H20)/H20 -> 0.099961792 | P19: =(I19-I20)/I20 -> -0.045902829
B20: 45689 | C20: 310 | D20: 308 | E20: 240 | F20: 343.125 | G20: 383.75 | H20: 3.7623125 | I20: 75.193 | J20: =(C20-C21)/C21 -> 0.029900332 | K20: =(D20-D21)/D21 -> 0.11594203 | L20: =(E20-E21)/E21 -> 0.08401084 | M20: =(F20-F21)/F21 -> -0.13895859 | N20: =(G20-G21)/G21 -> 0.11393324 | O20: =(H20-H21)/H21 -> 0.0082763177 | P20: =(I20-I21)/I21 -> -0.038377834
B21: 45658 | C21: 301 | D21: 276 | E21: 221.4 | F21: 398.5 | G21: 344.5 | H21: 3.73143 | I21: 78.193913 | J21: =(C21-C22)/C22 -> 0.11481481 | K21: =(D21-D22)/D22 -> 0.13114754 | L21: =(E21-E22)/E22 -> 0.0057921635 | M21: =(F21-F22)/F22 -> -0.039759036 | N21: =(G21-G22)/G22 -> 0.1024 | O21: =(H21-H22)/H22 -> 0.1027051 | P21: =(I21-I22)/I22 -> 0.067818379 | R21: PPAN = 0.280558110643*PPAN(-1) + 0.15041224611*PPAN(-2) - 0.188812610795*AMMONIA(-1) + 0.259276330013*AMMONIA(-2) + 0.249001945549*BALTIC_AN(-1) - 0.0911542671384*BALTIC_AN(-2) - 11.8844751787*NATURAL_GAS(-1) + 5.64643067713*NATURAL_GAS(-2) + 0.185696475006*UREA(-1) + 0.247343345212*UREA(-2) - 3.75210437468 | AD21: PPAN = 0.128313602811*PPAN(-1) - 0.463209414397*PPAN(-2) + 0.379422553201*HDAN(-1) + 0.600579570329*HDAN(-2) + 0.515891500331*BALTIC_AN(-1) - 0.0731750301725*BALTIC_AN(-2) - 0.0618573337801*AMMONIA(-1) + 0.179051366468*AMMONIA(-2) + 0.173303170283*UREA(-1) - 0.143779748569*UREA(-2) - 9.81173830345*NATURAL_GAS(-1) + 1.28656399894*NATURAL_GAS(-2) + 3.13148084685
B22: 45627 | C22: 270 | D22: 244 | E22: 220.125 | F22: 415 | G22: 312.5 | H22: 3.3838875 | I22: 73.227727 | J22: =(C22-C23)/C23 -> 0 | K22: =(D22-D23)/D23 -> -0.079245283 | L22: =(E22-E23)/E23 -> -0.075105042 | M22: =(F22-F23)/F23 -> -0.034883721 | N22: =(G22-G23)/G23 -> -0.012013911 | O22: =(H22-H23)/H23 -> 0.15587693 | P22: =(I22-I23)/I23 -> -0.0038205634
B23: 45597 | C23: 270 | D23: 265 | E23: 238 | F23: 430 | G23: 316.3 | H23: 2.92755 | I23: 73.508571 | J23: =(C23-C24)/C24 -> 0 | K23: =(D23-D24)/D24 -> 0.023166023 | L23: =(E23-E24)/E24 -> -0.018556701 | M23: =(F23-F24)/F24 -> 0 | N23: =(G23-G24)/G24 -> -0.017320388 | O23: =(H23-H24)/H24 -> 0.126284 | P23: =(I23-I24)/I24 -> -0.023356338
B24: 45566 | C24: 270 | D24: 259 | E24: 242.5 | F24: 430 | G24: 321.875 | H24: 2.5993 | I24: 75.266522 | J24: =(C24-C25)/C25 -> 0.071428571 | K24: =(D24-D25)/D25 -> 0.13100437 | L24: =(E24-E25)/E25 -> -0.022670025 | M24: =(F24-F25)/F25 -> 0.10610932 | N24: =(G24-G25)/G25 -> 0.066252588 | O24: =(H24-H25)/H25 -> 0.094874292 | P24: =(I24-I25)/I25 -> 0.030235076
B25: 45536 | C25: 252 | D25: 229 | E25: 248.125 | F25: 388.75 | G25: 301.875 | H25: 2.3740625 | I25: 73.057619 | J25: =(C25-C26)/C26 -> -0.090252708 | K25: =(D25-D26)/D26 -> -0.084 | L25: =(E25-E26)/E26 -> 0.038179916 | M25: =(F25-F26)/F26 -> 0.1251809 | N25: =(G25-G26)/G26 -> -0.0037128713 | O25: =(H25-H26)/H26 -> 0.14240876 | P25: =(I25-I26)/I26 -> -0.075438119
B26: 45505 | C26: 277 | D26: 250 | E26: 239 | F26: 345.5 | G26: 303 | H26: 2.07812 | I26: 79.018636 | J26: =(C26-C27)/C27 -> 0.018382353 | K26: =(D26-D27)/D27 -> -0.031007752 | L26: =(E26-E27)/E27 -> 0.074157303 | M26: =(F26-F27)/F27 -> 0.13278689 | N26: =(G26-G27)/G27 -> -0.018623482 | O26: =(H26-H27)/H27 -> -0.075044787 | P26: =(I26-I27)/I27 -> -0.059846964
B27: 45474 | C27: 272 | D27: 258 | E27: 222.5 | F27: 305 | G27: 308.75 | H27: 2.246725 | I27: 84.048696 | J27: =(C27-C28)/C28 -> 0.0074074074 | K27: =(D27-D28)/D28 -> 0.12173913 | L27: =(E27-E28)/E28 -> 0.095384615 | M27: =(F27-F28)/F28 -> 0.0472103 | N27: =(G27-G28)/G28 -> 0.046610169 | O27: =(H27-H28)/H28 -> -0.19999466 | P27: =(I27-I28)/I28 -> 0.013642424
B28: 45444 | C28: 270 | D28: 230 | E28: 203.125 | F28: 291.25 | G28: 295 | H28: 2.8083875 | I28: 82.9175 | J28: =(C28-C29)/C29 -> -0.1 | K28: =(D28-D29)/D29 -> -0.11538462 | L28: =(E28-E29)/E29 -> 0.1130137 | M28: =(F28-F29)/F29 -> 0.04954955 | N28: =(G28-G29)/G29 -> 0.1752988 | O28: =(H28-H29)/H29 -> 0.17451696 | P28: =(I28-I29)/I29 -> -0.0016424638
B29: 45413 | C29: 300 | D29: 260 | E29: 182.5 | F29: 277.5 | G29: 251 | H29: 2.3911 | I29: 83.053913 | J29: =(C29-C30)/C30 -> -0.090909091 | K29: =(D29-D30)/D30 -> -0.13333333 | L29: =(E29-E30)/E30 -> -0.11246201 | M29: =(F29-F30)/F30 -> 0.042743072 | N29: =(G29-G30)/G30 -> -0.061682243 | O29: =(H29-H30)/H30 -> 0.35143842 | P29: =(I29-I30)/I30 -> -0.066542991 | S29: 3-р сар | U29: 4-р сар
B30: 45383 | C30: 330 | D30: 300 | E30: 205.625 | F30: 266.125 | G30: 267.5 | H30: 1.7693 | I30: 88.974545 | J30: =(C30-C31)/C31 -> 0 | K30: =(D30-D31)/D31 -> 0 | L30: =(E30-E31)/E31 -> -0.10597826 | M30: =(F30-F31)/F31 -> -0.12745902 | N30: =(G30-G31)/G31 -> -0.11716172 | O30: =(H30-H31)/H31 -> 0.013745409 | P30: =(I30-I31)/I31 -> 0.047234574 | S30: Томъёоны үнэлгээ | T30: Тооцоолсон үнэлгээ | U30: Томъёоны үнэлгээ | V30: Тооцоолсон үнэлгээ
B31: 45352 | C31: 330 | D31: 300 | E31: 230 | F31: 305 | G31: 303 | H31: 1.74531 | I31: 84.961429 | J31: =(C31-C32)/C32 -> 0 | K31: =(D31-D32)/D32 -> -0.032258065 | L31: =(E31-E32)/E32 -> 0.098507463 | M31: =(F31-F32)/F32 -> -0.061538462 | N31: =(G31-G32)/G32 -> -0.013832384 | O31: =(H31-H32)/H32 -> -0.062392221 | P31: =(I31-I32)/I32 -> 0.038702691 | R31: ppan | S31: =0.280558110643*C8 + 0.15041224611*C9 - 0.188812610795*F8 + 0.259276330013*F9 + 0.249001945549*E8 - 0.0911542671384*E9 - 11.8844751787*H8 + 5.64643067713*H9 + 0.185696475006*G8 + 0.247343345212*G9 - 3.75210437468+20 -> 429.43103 | T31: =S31*1.15 -> 493.84568 | U31: =0.280558110643*C7+ 0.15041224611*C8 - 0.188812610795*F7 + 0.259276330013*F8 + 0.249001945549*E7 - 0.0911542671384*E8 - 11.8844751787*H7 + 5.64643067713*H8 + 0.185696475006*G7 + 0.247343345212*G8 - 3.75210437468+20 -> 494.67004 | V31: =U31*1.15 -> 568.87055 | W31: =0.280558110643*E7+ 0.15041224611*E8 - 0.188812610795*H7 + 0.259276330013*H8 + 0.249001945549*G7 - 0.0911542671384*G8 - 11.8844751787*J7 + 5.64643067713*J8 + 0.185696475006*I7 + 0.247343345212*I8 - 3.75210437468+20 -> 320.37051 | X31: =W31*1.15 -> 368.42609 | Y31: =0.280558110643*C5+ 0.15041224611*C6 - 0.188812610795*F5 + 0.259276330013*F6 + 0.249001945549*E5 - 0.0911542671384*E6 - 11.8844751787*H5 + 5.64643067713*H6 + 0.185696475006*G5 + 0.247343345212*G6 - 3.75210437468+20 -> 691.8678
B32: 45323 | C32: 330 | D32: 310 | E32: 209.375 | F32: 325 | G32: 307.25 | H32: 1.86145 | I32: 81.795714 | J32: =(C32-C33)/C33 -> 0 | K32: =(D32-D33)/D33 -> 0 | L32: =(E32-E33)/E33 -> 0.15120275 | M32: =(F32-F33)/F33 -> -0.23529412 | N32: =(G32-G33)/G33 -> 0.13796296 | O32: =(H32-H33)/H33 -> -0.33319602 | P32: =(I32-I33)/I33 -> 0.033949112
B33: 45292 | C33: 330 | D33: 310 | E33: 181.875 | F33: 425 | G33: 270 | H33: 2.7916 | I33: 79.11 | J33: =(C33-C34)/C34 -> 0 | K33: =(D33-D34)/D34 -> 0.033333333 | L33: =(E33-E34)/E34 -> 0.030453258 | M33: =(F33-F34)/F34 -> -0.082073434 | N33: =(G33-G34)/G34 -> -0.044247788 | O33: =(H33-H34)/H34 -> 0.082972549 | P33: =(I33-I34)/I34 -> 0.020235083 | S33: =0.128313602811*C8 - 0.463209414397*C9 + 0.379422553201*D8 + 0.600579570329*D9 + 0.515891500331*E8 - 0.0731750301725*E9 - 0.0618573337801*F8 + 0.179051366468*F9 + 0.173303170283*G8 - 0.143779748569*G9 - 9.81173830345*H8 + 1.28656399894*H9 + 3.13148084685 -> 427.52884 | T33: =S33*1.3 -> 555.7875
B34: 45261 | C34: 330 | D34: 300 | E34: 176.5 | F34: 463 | G34: 282.5 | H34: 2.57772 | I34: 77.540952 | J34: =(C34-C35)/C35 -> 0.17857143 | K34: =(D34-D35)/D35 -> 0 | L34: =(E34-E35)/E35 -> -0.10178117 | M34: =(F34-F35)/F35 -> -0.15818182 | N34: =(G34-G35)/G35 -> -0.17367459 | O34: =(H34-H35)/H35 -> -0.1798145 | P34: =(I34-I35)/I35 -> -0.056522896
B35: 45231 | C35: 280 | D35: 300 | E35: 196.5 | F35: 550 | G35: 341.875 | H35: 3.14285 | I35: 82.186364 | J35: =(C35-C36)/C36 -> 0 | K35: =(D35-D36)/D36 -> 0.2 | L35: =(E35-E36)/E36 -> -0.10934844 | M35: =(F35-F36)/F36 -> 0 | N35: =(G35-G36)/G36 -> -0.040350877 | O35: =(H35-H36)/H36 -> 0.0080506776 | P35: =(I35-I36)/I36 -> -0.076015024
B36: 45200 | C36: 280 | D36: 250 | E36: 220.625 | F36: 550 | G36: 356.25 | H36: 3.11775 | I36: 88.947727 | J36: =(C36-C37)/C37 -> 0 | K36: =(D36-D37)/D37 -> 0 | L36: =(E36-E37)/E37 -> -0.13818359 | M36: =(F36-F37)/F37 -> 0.22767857 | N36: =(G36-G37)/G37 -> 0.020481237 | O36: =(H36-H37)/H37 -> 0.16020527 | P36: =(I36-I37)/I37 -> -0.04020149
B37: 45170 | C37: 280 | D37: 250 | E37: 256 | F37: 448 | G37: 349.1 | H37: 2.68724 | I37: 92.673333 | J37: =(C37-C38)/C38 -> 0 | K37: =(D37-D38)/D38 -> 0 | L37: =(E37-E38)/E38 -> 0.18381503 | M37: =(F37-F38)/F38 -> 0.3423221 | N37: =(G37-G38)/G38 -> -0.023496503 | O37: =(H37-H38)/H38 -> 0.01841472 | P37: =(I37-I38)/I38 -> 0.088120532
B38: 45139 | C38: 280 | D38: 250 | E38: 216.25 | F38: 333.75 | G38: 357.5 | H38: 2.63865 | I38: 85.168261 | J38: =(C38-C39)/C39 -> -0.15151515 | K38: =(D38-D39)/D39 -> -0.16666667 | L38: =(E38-E39)/E39 -> 0.44769874 | M38: =(F38-F39)/F39 -> 0.2961165 | N38: =(G38-G39)/G39 -> 0.16925593 | O38: =(H38-H39)/H39 -> 0.00069686411 | P38: =(I38-I39)/I39 -> 0.063154081
B39: 45108 | C39: 330 | D39: 300 | E39: 149.375 | F39: 257.5 | G39: 305.75 | H39: 2.6368125 | I39: 80.109048 | J39: =(C39-C40)/C40 -> 0 | K39: =(D39-D40)/D40 -> 0 | L39: =(E39-E40)/E40 -> 0.094322344 | M39: =(F39-F40)/F40 -> 0.25 | N39: =(G39-G40)/G40 -> 0.20326643 | O39: =(H39-H40)/H40 -> 0.073668813 | P39: =(I39-I40)/I40 -> 0.068476794
B40: 45078 | C40: 330 | D40: 300 | E40: 136.5 | F40: 206 | G40: 254.1 | H40: 2.45589 | I40: 74.975 | J40: =(C40-C41)/C41 -> 0 | K40: =(D40-D41)/D41 -> -0.34782609 | L40: =(E40-E41)/E41 -> -0.2227758 | M40: =(F40-F41)/F41 -> -0.14611399 | N40: =(G40-G41)/G41 -> -0.14046512 | O40: =(H40-H41)/H41 -> 0.067963994 | P40: =(I40-I41)/I41 -> -0.010196936
B41: 45047 | C41: 330 | D41: 460 | E41: 175.625 | F41: 241.25 | G41: 295.625 | H41: 2.2996 | I41: 75.747391 | J41: =(C41-C42)/C42 -> -0.4 | K41: =(D41-D42)/D42 -> 0 | L41: =(E41-E42)/E42 -> -0.14224664 | M41: =(F41-F42)/F42 -> -0.10854503 | N41: =(G41-G42)/G42 -> 0.032751092 | O41: =(H41-H42)/H42 -> 0.051029503 | P41: =(I41-I42)/I42 -> -0.093236553
...

Sheet weekly-forecast
D1: Current commodity price | K1: Monthly price | Q1: Weekly % | X1: Monthly % | AE1: Yearly %
A2: Date | B2: Year | C2: Month | D2: PPAN | E2: HDAN | F2: Baltic AN | G2: Ammonia | H2: Urea | I2: Natural_gas | J2: Brent | K2: PPAN | L2: HDAN | M2: Baltic AN | N2: Ammonia | O2: Urea | P2: Natural_gas | Q2: Baltic AN | R2: Ammonia | S2: Urea | T2: Natural_gas | U2: Brent | V2: PPAN | W2: HDAN | X2: Baltic AN | Y2: Ammonia | Z2: Urea | AA2: Natural_gas | AB2: Brent | AC2: PPAN | AD2: HDAN | AE2: Baltic AN | AF2: Ammonia | AG2: Urea | AH2: Natural_gas | AI2: Brent | AJ2: PPAN | AK2: HDAN | AM2: HDAN = 0.080991528041*HDAN(-1) + 0.303754553817*HDAN(-2) - 0.25338201366*AMMONIA(-1) + 0.269148503584*AMMONIA(-2) + 0.00378757678133*BALTIC_AN(-1) + 0.43547234846*BALTIC_AN(-2) - 12.2555082812*NATURAL_GAS(-1) + 15.7710625006*NATURAL_GAS(-2) + 0.517281394734*UREA(-1) - 0.299449478792*UREA(-2) - 3.00478655786
K3: =AVERAGE(D4:D6) -> 467.90461 | L3: =AVERAGE(E4:E6) -> 459.06484 | M3: =AVERAGE(F3:F6) -> 392.5 | N3: =AVERAGE(G3:G6) -> 770 | O3: =AVERAGE(H3:H6) -> 362 | P3: =AVERAGE(I3:I6) -> 3.239
A4: =A5+7 -> 46220 | B4: =YEAR(A4) -> 2026 | C4: =MONTH(A4) -> 7 | D4: =0.280558110643*D5 + 0.15041224611*D6 - 0.188812610795*G5 + 0.259276330013*G6 + 0.249001945549*F5 - 0.0911542671384*F6 - 11.8844751787*I5 + 5.64643067713*I6 + 0.185696475006*H5 + 0.247343345212*H6- 3.75210437468 -> 452.43013 | E4: =0.080991528041*E5 + 0.303754553817*E6 - 0.25338201366*G5 + 0.269148503584*G6 + 0.00378757678133*F5 + 0.43547234846*F6 - 12.2555082812*I5 + 15.7710625006*I6 + 0.517281394734*H5 - 0.299449478792*H6 - 3.00478655786 -> 450.86301
A5: =A6+7 -> 46213 | B5: =YEAR(A5) -> 2026 | C5: =MONTH(A5) -> 7 | D5: =0.280558110643*D6 + 0.15041224611*D7 - 0.188812610795*G6 + 0.259276330013*G7 + 0.249001945549*F6 - 0.0911542671384*F7 - 11.8844751787*I6 + 5.64643067713*I7 + 0.185696475006*H6 + 0.247343345212*H7- 3.75210437468 -> 463.55567 | E5: =0.080991528041*E6 + 0.303754553817*E7 - 0.25338201366*G6 + 0.269148503584*G7 + 0.00378757678133*F6 + 0.43547234846*F7 - 12.2555082812*I6 + 15.7710625006*I7 + 0.517281394734*H6 - 0.299449478792*H7 - 3.00478655786 -> 459.23858 | F5: 392.5 | G5: 770 | H5: 362 | I5: 3.239
A6: =A7+7 -> 46206 | B6: =YEAR(A6) -> 2026 | C6: =MONTH(A6) -> 7 | D6: =0.280558110643*D7 + 0.15041224611*D8 - 0.188812610795*G7 + 0.259276330013*G8 + 0.249001945549*F7 - 0.0911542671384*F8 - 11.8844751787*I7 + 5.64643067713*I8 + 0.185696475006*H7 + 0.247343345212*H8- 3.75210437468 -> 487.72803 | E6: =0.080991528041*E7 + 0.303754553817*E8 - 0.25338201366*G7 + 0.269148503584*G8 + 0.00378757678133*F7 + 0.43547234846*F8 - 12.2555082812*I7 + 15.7710625006*I8 + 0.517281394734*H7 - 0.299449478792*H8 - 3.00478655786 -> 467.09294 | F6: 392.5 | G6: 770 | H6: 362 | I6: 3.239
A7: =A8+7 -> 46199 | B7: =YEAR(A7) -> 2026 | C7: =MONTH(A7) -> 6 | D7: =0.280558110643*D8 + 0.15041224611*D9 - 0.188812610795*G8 + 0.259276330013*G9 + 0.249001945549*F8 - 0.0911542671384*F9 - 11.8844751787*I8 + 5.64643067713*I9 + 0.185696475006*H8 + 0.247343345212*H9- 3.75210437468 -> 516.60723 | E7: =0.080991528041*E8 + 0.303754553817*E9 - 0.25338201366*G8 + 0.269148503584*G9 + 0.00378757678133*F8 + 0.43547234846*F9 - 12.2555082812*I8 + 15.7710625006*I9 + 0.517281394734*H8 - 0.299449478792*H9 - 3.00478655786 -> 492.57218 | F7: 392.5 | G7: 770 | H7: 362 | I7: 3.239 | K7: =AVERAGE(D7:D10) -> 576.44977 | L7: =AVERAGE(E7:E10) -> 519.49285 | M7: =AVERAGE(F7:F10) -> 417.5 | N7: =AVERAGE(G7:G10) -> 790 | O7: =AVERAGE(H7:H10) -> 406.125 | P7: =AVERAGE(I7:I10) -> 3.20225 | Q7: =(F7-F8)/F8 -> -0.05988024 | R7: =(G7-G8)/G8 -> -0.025316456 | S7: =(H7-H8)/H8 -> -0.083544304 | T7: =(I7-I8)/I8 -> 0.015360502 | V7: =(D6-D7)/D7 -> -0.05590166 | W7: =(E6-E7)/E7 -> -0.051726911 | X7: =(F7-F11)/F11 -> -0.16042781 | Y7: =(G7-G11)/G11 -> -0.0375 | Z7: =(H7-H11)/H11 -> -0.33577982 | AA7: =(I7-I11)/I11 -> 0.068976898 | AC7: =(D7-D11)/D11 -> -0.23642268 | AD7: =(E7-E11)/E11 -> -0.16098818 | AE7: =(F7-F59)/F59 -> 0.30833333 | AF7: =(G7-G59)/G59 -> 1.6551724 | AG7: =(H7-H59)/H59 -> -0.16300578 | AH7: =(I7-I59)/I59 -> -0.081968142 | AI7: =(J7-J59)/J59 -> -1 | AJ7: =(D7-D59)/D59 -> 0.64002294 | AK7: =(E7-E59)/E59 -> 0.59926031
A8: =A9+7 -> 46192 | B8: =YEAR(A8) -> 2026 | C8: =MONTH(A8) -> 6 | D8: =0.280558110643*D9 + 0.15041224611*D10 - 0.188812610795*G9 + 0.259276330013*G10 + 0.249001945549*F9 - 0.0911542671384*F10 - 11.8844751787*I9 + 5.64643067713*I10 + 0.185696475006*H9 + 0.247343345212*H10- 3.75210437468 -> 551.69571 | E8: =0.080991528041*E9 + 0.303754553817*E10 - 0.25338201366*G9 + 0.269148503584*G10 + 0.00378757678133*F9 + 0.43547234846*F10 - 12.2555082812*I9 + 15.7710625006*I10 + 0.517281394734*H9 - 0.299449478792*H10 - 3.00478655786 -> 493.15026 | F8: 417.5 | G8: 790 | H8: 395 | I8: 3.19 | Q8: =(F8-F9)/F9 -> 0 | R8: =(G8-G9)/G9 -> -0.0125 | S8: =(H8-H9)/H9 -> 0 | T8: =(I8-I9)/I9 -> 0.012698413 | V8: =(D7-D8)/D8 -> -0.063601152 | W8: =(E7-E8)/E8 -> -0.0011722234 | X8: =(F8-F12)/F12 -> -0.165 | Y8: =(G8-G12)/G12 -> 0.036065574 | Z8: =(H8-H12)/H12 -> -0.32188841 | AA8: =(I8-I12)/I12 -> 0.056291391 | AC8: =(D8-D12)/D12 -> -0.21724401 | AD8: =(E8-E12)/E12 -> -0.16503225 | AE8: =(F8-F60)/F60 -> 0.81521739 | AF8: =(G8-G60)/G60 -> 1.7241379 | AG8: =(H8-H60)/H60 -> 0.0063694268 | AH8: =(I8-I60)/I60 -> -0.17330742 | AI8: =(J8-J60)/J60 -> -1 | AJ8: =(D8-D60)/D60 -> 0.75141495 | AK8: =(E8-E60)/E60 -> 0.6011372
A9: =A10+7 -> 46185 | B9: =YEAR(A9) -> 2026 | C9: =MONTH(A9) -> 6 | D9: =0.280558110643*D10 + 0.15041224611*D11 - 0.188812610795*G10 + 0.259276330013*G11 + 0.249001945549*F10 - 0.0911542671384*F11 - 11.8844751787*I10 + 5.64643067713*I11 + 0.185696475006*H10 + 0.247343345212*H11- 3.75210437468 -> 601.61729 | E9: =0.080991528041*E10 + 0.303754553817*E11 - 0.25338201366*G10 + 0.269148503584*G11 + 0.00378757678133*F10 + 0.43547234846*F11 - 12.2555082812*I10 + 15.7710625006*I11 + 0.517281394734*H10 - 0.299449478792*H11 - 3.00478655786 -> 528.29021 | F9: 417.5 | G9: 800 | H9: 395 | I9: 3.15 | Q9: =(F9-F10)/F10 -> -0.056497175 | R9: =(G9-G10)/G10 -> 0 | S9: =(H9-H10)/H10 -> -0.16402116 | T9: =(I9-I10)/I10 -> -0.024767802 | V9: =(D8-D9)/D9 -> -0.082978971 | W9: =(E8-E9)/E9 -> -0.066516376 | X9: =(F9-F13)/F13 -> -0.165 | Y9: =(G9-G13)/G13 -> 0.049180328 | Z9: =(H9-H13)/H13 -> -0.36032389 | AA9: =(I9-I13)/I13 -> 0.10526316 | AC9: =(D9-D13)/D13 -> -0.16841357 | AD9: =(E9-E13)/E13 -> -0.13846561 | AE9: =(F9-F61)/F61 -> 0.81521739 | AF9: =(G9-G61)/G61 -> 1.7586207 | AG9: =(H9-H61)/H61 -> 0.12056738 | AH9: =(I9-I61)/I61 -> -0.11257606 | AI9: =(J9-J61)/J61 -> -1 | AJ9: =(D9-D61)/D61 -> 0.90989617 | AK9: =(E9-E61)/E61 -> 0.71522795
A10: 46178 | B10: =YEAR(A10) -> 2026 | C10: =MONTH(A10) -> 6 | D10: =0.280558110643*D11 + 0.15041224611*D12 - 0.188812610795*G11 + 0.259276330013*G12 + 0.249001945549*F11 - 0.0911542671384*F12 - 11.8844751787*I11 + 5.64643067713*I12 + 0.185696475006*H11 + 0.247343345212*H12- 3.75210437468 -> 635.87885 | E10: =0.080991528041*E11 + 0.303754553817*E12 - 0.25338201366*G11 + 0.269148503584*G12 + 0.00378757678133*F11 + 0.43547234846*F12 - 12.2555082812*I11 + 15.7710625006*I12 + 0.517281394734*H11 - 0.299449478792*H12 - 3.00478655786 -> 563.95876 | F10: 442.5 | G10: 800 | H10: 472.5 | I10: 3.23 | Q10: =(F10-F11)/F11 -> -0.053475936 | R10: =(G10-G11)/G11 -> 0 | S10: =(H10-H11)/H11 -> -0.13302752 | T10: =(I10-I11)/I11 -> 0.066006601 | V10: =(D9-D10)/D10 -> -0.053880635 | W10: =(E9-E10)/E10 -> -0.063246736 | X10: =(F10-F14)/F14 -> -0.115 | Y10: =(G10-G14)/G14 -> 0.049180328 | Z10: =(H10-H14)/H14 -> -0.30769231 | AA10: =(I10-I14)/I14 -> 0.15770609 | AC10: =(D10-D14)/D14 -> -0.11092988 | AD10: =(E10-E14)/E14 -> -0.089727715 | AE10: =(F10-F62)/F62 -> 1.0344828 | AF10: =(G10-G62)/G62 -> 1.7586207 | AG10: =(H10-H62)/H62 -> 0.34042553 | AH10: =(I10-I62)/I62 -> -0.13139354 | AI10: =(J10-J62)/J62 -> -1 | AJ10: =(D10-D62)/D62 -> 1.018663 | AK10: =(E10-E62)/E62 -> 0.83103493
A11: 46171 | B11: =YEAR(A11) -> 2026 | C11: =MONTH(A11) -> 5 | D11: =0.280558110643*D12 + 0.15041224611*D13 - 0.188812610795*G12 + 0.259276330013*G13 + 0.249001945549*F12 - 0.0911542671384*F13 - 11.8844751787*I12 + 5.64643067713*I13 + 0.185696475006*H12 + 0.247343345212*H13- 3.75210437468 -> 676.56177 | E11: =0.080991528041*E12 + 0.303754553817*E13 - 0.25338201366*G12 + 0.269148503584*G13 + 0.00378757678133*F12 + 0.43547234846*F13 - 12.2555082812*I12 + 15.7710625006*I13 + 0.517281394734*H12 - 0.299449478792*H13 - 3.00478655786 -> 587.0861 | F11: 467.5 | G11: 800 | H11: 545 | I11: 3.03 | K11: =AVERAGEA(D11:D15) -> 708.97426 | L11: =AVERAGEA(E11:E15) -> 603.80602 | M11: =AVERAGEA(F11:F15) -> 495.5 | N11: =AVERAGEA(G11:G15) -> 770 | O11: =AVERAGEA(H11:H15) -> 629 | P11: =AVERAGEA(I11:I15) -> 2.86 | Q11: =(F11-F12)/F12 -> -0.065 | R11: =(G11-G12)/G12 -> 0.049180328 | S11: =(H11-H12)/H12 -> -0.064377682 | T11: =(I11-I12)/I12 -> 0.0033112583 | V11: =(D10-D11)/D11 -> -0.060131864 | W11: =(E10-E11)/E11 -> -0.039393434 | X11: =(F11-F15)/F15 -> -0.083333333 | Y11: =(G11-G15)/G15 -> 0.049180328 | Z11: =(H11-H15)/H15 -> -0.24041812 | AA11: =(I11-I15)/I15 -> 0.16091954 | AC11: =(D11-D15)/D15 -> -0.066582792 | AD11: =(E11-E15)/E15 -> -0.03531122 | AE11: =(F11-F63)/F63 -> 1.2261905 | AF11: =(G11-G63)/G63 -> 1.6446281 | AG11: =(H11-H63)/H63 -> 0.53521127 | AH11: =(I11-I63)/I63 -> -0.10691917 | AI11: =(J11-J63)/J63 -> -1 | AJ11: =(D11-D63)/D63 -> 1.0817285 | AK11: =(E11-E63)/E63 -> 0.82892865
A12: 46164 | B12: =YEAR(A12) -> 2026 | C12: =MONTH(A12) -> 5 | D12: =0.280558110643*D13 + 0.15041224611*D14 - 0.188812610795*G13 + 0.259276330013*G14 + 0.249001945549*F13 - 0.0911542671384*F14 - 11.8844751787*I13 + 5.64643067713*I14 + 0.185696475006*H13 + 0.247343345212*H14- 3.75210437468 -> 704.81186 | E12: =0.080991528041*E13 + 0.303754553817*E14 - 0.25338201366*G13 + 0.269148503584*G14 + 0.00378757678133*F13 + 0.43547234846*F14 - 12.2555082812*I13 + 15.7710625006*I14 + 0.517281394734*H13 - 0.299449478792*H14 - 3.00478655786 -> 590.62192 | F12: 500 | G12: 762.5 | H12: 582.5 | I12: 3.02 | Q12: =(F12-F13)/F13 -> 0 | R12: =(G12-G13)/G13 -> 0 | S12: =(H12-H13)/H13 -> -0.056680162 | T12: =(I12-I13)/I13 -> 0.059649123 | V12: =(D11-D12)/D12 -> -0.040081748 | W12: =(E11-E12)/E12 -> -0.0059866172 | X12: =(F12-F16)/F16 -> -0.069767442 | Y12: =(G12-G16)/G16 -> 0.089285714 | Z12: =(H12-H16)/H16 -> -0.18815331 | AA12: =(I12-I16)/I16 -> 0.12686567 | AC12: =(D12-D16)/D16 -> 0.0069967505 | AD12: =(E12-E16)/E16 -> 0.022288401 | AE12: =(F12-F64)/F64 -> 1.2988506 | AF12: =(G12-G64)/G64 -> 1.5206612 | AG12: =(H12-H64)/H64 -> 0.64084507 | AH12: =(I12-I64)/I64 -> -0.084571082 | AI12: =(J12-J64)/J64 -> -1 | AJ12: =(D12-D64)/D64 -> 1.1686519 | AK12: =(E12-E64)/E64 -> 0.83994369
A13: 46157 | B13: =YEAR(A13) -> 2026 | C13: =MONTH(A13) -> 5 | D13: =0.280558110643*D14 + 0.15041224611*D15 - 0.188812610795*G14 + 0.259276330013*G15 + 0.249001945549*F14 - 0.0911542671384*F15 - 11.8844751787*I14 + 5.64643067713*I15 + 0.185696475006*H14 + 0.247343345212*H15- 3.75210437468 -> 723.45732 | E13: =0.080991528041*E14 + 0.303754553817*E15 - 0.25338201366*G14 + 0.269148503584*G15 + 0.00378757678133*F14 + 0.43547234846*F15 - 12.2555082812*I14 + 15.7710625006*I15 + 0.517281394734*H14 - 0.299449478792*H15 - 3.00478655786 -> 613.19689 | F13: 500 | G13: 762.5 | H13: 617.5 | I13: 2.85 | Q13: =(F13-F14)/F14 -> 0 | R13: =(G13-G14)/G14 -> 0 | S13: =(H13-H14)/H14 -> -0.095238095 | T13: =(I13-I14)/I14 -> 0.021505376 | V13: =(D12-D13)/D13 -> -0.025772719 | W13: =(E12-E13)/E13 -> -0.0368152 | X13: =(F13-F17)/F17 -> 0 | Y13: =(G13-G17)/G17 -> 0.089285714 | Z13: =(H13-H17)/H17 -> -0.13937282 | AA13: =(I13-I17)/I17 -> 0.08365019 | AC13: =(D13-D17)/D17 -> 0.078291064 | AD13: =(E13-E17)/E17 -> 0.10179968 | AE13: =(F13-F65)/F65 -> 1.3255814 | AF13: =(G13-G65)/G65 -> 1.5206612 | AG13: =(H13-H65)/H65 -> 0.76428571 | AH13: =(I13-I65)/I65 -> -0.18482924 | AI13: =(J13-J65)/J65 -> -1 | AJ13: =(D13-D65)/D65 -> 1.2260225 | AK13: =(E13-E65)/E65 -> 0.91027069
A14: 46150 | B14: =YEAR(A14) -> 2026 | C14: =MONTH(A14) -> 5 | D14: =0.280558110643*D15 + 0.15041224611*D16 - 0.188812610795*G15 + 0.259276330013*G16 + 0.249001945549*F15 - 0.0911542671384*F16 - 11.8844751787*I15 + 5.64643067713*I16 + 0.185696475006*H15 + 0.247343345212*H16- 3.75210437468 -> 715.21788 | E14: =0.080991528041*E15 + 0.303754553817*E16 - 0.25338201366*G15 + 0.269148503584*G16 + 0.00378757678133*F15 + 0.43547234846*F16 - 12.2555082812*I15 + 15.7710625006*I16 + 0.517281394734*H15 - 0.299449478792*H16 - 3.00478655786 -> 619.54952 | F14: 500 | G14: 762.5 | H14: 682.5 | I14: 2.79 | Q14: =(F14-F15)/F15 -> -0.019607843 | R14: =(G14-G15)/G15 -> 0 | S14: =(H14-H15)/H15 -> -0.048780488 | T14: =(I14-I15)/I15 -> 0.068965517 | V14: =(D13-D14)/D14 -> 0.011520187 | W14: =(E13-E14)/E14 -> -0.010253631 | X14: =(F14-F18)/F18 -> 0.13636364 | Y14: =(G14-G18)/G18 -> 0.1380597 | Z14: =(H14-H18)/H18 -> -0.055363322 | AA14: =(I14-I18)/I18 -> 0.016541573 | AC14: =(D14-D18)/D18 -> 0.15291826 | AD14: =(E14-E18)/E18 -> 0.085547437 | AE14: =(F14-F66)/F66 -> 1.3255814 | AF14: =(G14-G66)/G66 -> 1.5206612 | AG14: =(H14-H66)/H66 -> 0.96402878 | AH14: =(I14-I66)/I66 -> -0.22590311 | AI14: =(J14-J66)/J66 -> -1 | AJ14: =(D14-D66)/D66 -> 1.2006704 | AK14: =(E14-E66)/E66 -> 0.93006082
A15: 46143 | B15: =YEAR(A15) -> 2026 | C15: =MONTH(A15) -> 5 | D15: =0.280558110643*D16 + 0.15041224611*D17 - 0.188812610795*G16 + 0.259276330013*G17 + 0.249001945549*F16 - 0.0911542671384*F17 - 11.8844751787*I16 + 5.64643067713*I17 + 0.185696475006*H16 + 0.247343345212*H17- 3.75210437468 -> 724.82248 | E15: =0.080991528041*E16 + 0.303754553817*E17 - 0.25338201366*G16 + 0.269148503584*G17 + 0.00378757678133*F16 + 0.43547234846*F17 - 12.2555082812*I16 + 15.7710625006*I17 + 0.517281394734*H16 - 0.299449478792*H17 - 3.00478655786 -> 608.57565 | F15: 510 | G15: 762.5 | H15: 717.5 | I15: 2.61 | Q15: =(F15-F16)/F16 -> -0.051162791 | R15: =(G15-G16)/G16 -> 0.089285714 | S15: =(H15-H16)/H16 -> 0 | T15: =(I15-I16)/I16 -> -0.026119403 | V15: =(D14-D15)/D15 -> -0.013250961 | W15: =(E14-E15)/E15 -> 0.018032068 | X15: =(F15-F19)/F19 -> 0.22891566 | Y15: =(G15-G19)/G19 -> 0.1509434 | Z15: =(H15-H19)/H19 -> -0.0034722222 | AA15: =(I15-I19)/I19 -> -0.083406497 | AC15: =(D15-D19)/D19 -> 0.23994169 | AD15: =(E15-E19)/E19 -> 0.20833245 | AE15: =(F15-F67)/F67 -> 1.372093 | AF15: =(G15-G67)/G67 -> 1.5206612 | AG15: =(H15-H67)/H67 -> 1.0647482 | AH15: =(I15-I67)/I67 -> -0.23194632 | AI15: =(J15-J67)/J67 -> -1 | AJ15: =(D15-D67)/D67 -> 1.230223 | AK15: =(E15-E67)/E67 -> 0.89587428
A16: =A17+7 -> 46136 | B16: =YEAR(A16) -> 2026 | C16: =MONTH(A16) -> 4 | D16: =0.280558110643*D17 + 0.15041224611*D18 - 0.188812610795*G17 + 0.259276330013*G18 + 0.249001945549*F17 - 0.0911542671384*F18 - 11.8844751787*I17 + 5.64643067713*I18 + 0.185696475006*H17 + 0.247343345212*H18- 3.75210437468 -> 699.91473 | E16: =0.080991528041*E17 + 0.303754553817*E18 - 0.25338201366*G17 + 0.269148503584*G18 + 0.00378757678133*F17 + 0.43547234846*F18 - 12.2555082812*I17 + 15.7710625006*I18 + 0.517281394734*H17 - 0.299449478792*H18 - 3.00478655786 -> 577.74491 | F16: 537.5 | G16: 700 | H16: 717.5 | I16: 2.68 | K16: =AVERAGE(D16:D19) -> 643.9401 | L16: =AVERAGE(E16:E19) -> 552.16517 | M16: =AVERAGE(F16:F19) -> 473.125 | N16: =AVERAGE(G16:G19) -> 683.125 | O16: =AVERAGE(H16:H19) -> 719.375 | P16: =AVERAGE(I16:I19) -> 2.725525 | Q16: =(F16-F17)/F17 -> 0.075 | R16: =(G16-G17)/G17 -> 0 | S16: =(H16-H17)/H17 -> 0 | T16: =(I16-I17)/I17 -> 0.019011407 | V16: =(D15-D16)/D16 -> 0.035586823 | W16: =(E15-E16)/E16 -> 0.053363917 | X16: =(F16-F20)/F20 -> 0.29518072 | Y16: =(G16-G20)/G20 -> 0.12 | Z16: =(H16-H20)/H20 -> 0.13438735 | AA16: =(I16-I20)/I20 -> -0.099462366 | AC16: =(D16-D20)/D20 -> 0.24545506 | AD16: =(E16-E20)/E20 -> 0.13063603 | AE16: =(F16-F68)/F68 -> 1.4431818 | AF16: =(G16-G68)/G68 -> 1.3140496 | AG16: =(H16-H68)/H68 -> 1.0797101 | AH16: =(I16-I68)/I68 -> -0.10139485 | AI16: =(J16-J68)/J68 -> -1 | AJ16: =(D16-D68)/D68 -> 1.2219515 | AK16: =(E16-E68)/E68 -> 0.89424562
A17: =A18+7 -> 46129 | B17: =YEAR(A17) -> 2026 | C17: =MONTH(A17) -> 4 | D17: =0.280558110643*D18 + 0.15041224611*D19 - 0.188812610795*G18 + 0.259276330013*G19 + 0.249001945549*F18 - 0.0911542671384*F19 - 11.8844751787*I18 + 5.64643067713*I19 + 0.185696475006*H18 + 0.247343345212*H19- 3.75210437468 -> 670.92954 | E17: =0.080991528041*E18 + 0.303754553817*E19 - 0.25338201366*G18 + 0.269148503584*G19 + 0.00378757678133*F18 + 0.43547234846*F19 - 12.2555082812*I18 + 15.7710625006*I19 + 0.517281394734*H18 - 0.299449478792*H19 - 3.00478655786 -> 556.54118 | F17: 500 | G17: 700 | H17: 717.5 | I17: 2.63 | Q17: =(F17-F18)/F18 -> 0.13636364 | R17: =(G17-G18)/G18 -> 0.044776119 | S17: =(H17-H18)/H18 -> -0.0069204152 | T17: =(I17-I18)/I18 -> -0.041754718 | U17: =(J17-J18)/J18 -> -1 | V17: =(D16-D17)/D17 -> 0.04320155 | W17: =(E16-E17)/E17 -> 0.038099134 | X17: =(F17-F21)/F21 -> 0.20481928 | Y17: =(G17-G21)/G21 -> 0.2173913 | Z17: =(H17-H21)/H21 -> 0.10810811 | AA17: =(I17-I21)/I21 -> -0.14510467 | AC17: =(D17-D21)/D21 -> 0.35541321 | AD17: =(E17-E21)/E21 -> 0.19686275 | AE17: =(F17-F69)/F69 -> 1.1978022 | AF17: =(G17-G69)/G69 -> 1.3140496 | AG17: =(H17-H69)/H69 -> 1.0797101 | AH17: =(I17-I69)/I69 -> -0.19975658 | AI17: =(J17-J69)/J69 -> -1 | AJ17: =(D17-D69)/D69 -> 1.129935 | AK17: =(E17-E69)/E69 -> 0.82472517
A18: =A19+7 -> 46122 | B18: =YEAR(A18) -> 2026 | C18: =MONTH(A18) -> 4 | D18: =0.280558110643*D19 + 0.15041224611*D20 - 0.188812610795*G19 + 0.259276330013*G20 + 0.249001945549*F19 - 0.0911542671384*F20 - 11.8844751787*I19 + 5.64643067713*I20 + 0.185696475006*H19 + 0.247343345212*H20- 3.75210437468 -> 620.35437 | E18: =0.080991528041*E19 + 0.303754553817*E20 - 0.25338201366*G19 + 0.269148503584*G20 + 0.00378757678133*F19 + 0.43547234846*F20 - 12.2555082812*I19 + 15.7710625006*I20 + 0.517281394734*H19 - 0.299449478792*H20 - 3.00478655786 -> 570.72543 | F18: 440 | G18: 670 | H18: 722.5 | I18: 2.7446 | J18: 103.44 | Q18: =(F18-F19)/F19 -> 0.060240964 | R18: =(G18-G19)/G19 -> 0.011320755 | S18: =(H18-H19)/H19 -> 0.0034722222 | T18: =(I18-I19)/I19 -> -0.036136962 | U18: =(J18-J19)/J19 -> -0.061938877 | V18: =(D17-D18)/D18 -> 0.081526252 | W18: =(E17-E18)/E18 -> -0.024853016 | X18: =(F18-F22)/F22 -> 0.17333333 | Y18: =(G18-G22)/G22 -> 0.21818182 | Z18: =(H18-H22)/H22 -> 0.20920502 | AA18: =(I18-I22)/I22 -> -0.12664673 | AB18: =(J18-J22)/J22 -> 0.0023255814 | AC18: =(D18-D22)/D22 -> 0.25324115 | AD18: =(E18-E22)/E22 -> 0.22736651 | AE18: =(F18-F70)/F70 -> 0.93406593 | AF18: =(G18-G70)/G70 -> 1.214876 | AG18: =(H18-H70)/H70 -> 1.0942029 | AH18: =(I18-I70)/I70 -> -0.23845727 | AI18: =(J18-J70)/J70 -> 0.54555827 | AJ18: =(D18-D70)/D70 -> 0.96937896 | AK18: =(E18-E70)/E70 -> 0.8712309
A19: =A20+7 -> 46115 | B19: =YEAR(A19) -> 2026 | C19: =MONTH(A19) -> 4 | D19: =0.280558110643*D20 + 0.15041224611*D21 - 0.188812610795*G20 + 0.259276330013*G21 + 0.249001945549*F20 - 0.0911542671384*F21 - 11.8844751787*I20 + 5.64643067713*I21 + 0.185696475006*H20 + 0.247343345212*H21- 3.75210437468 -> 584.56174 | E19: =0.080991528041*E20 + 0.303754553817*E21 - 0.25338201366*G20 + 0.269148503584*G21 + 0.00378757678133*F20 + 0.43547234846*F21 - 12.2555082812*I20 + 15.7710625006*I21 + 0.517281394734*H20 - 0.299449478792*H21 - 3.00478655786 -> 503.64918 | F19: 415 | G19: 662.5 | H19: 720 | I19: 2.8475 | J19: 110.27 | Q19: =(F19-F20)/F20 -> 0 | R19: =(G19-G20)/G20 -> 0.06 | S19: =(H19-H20)/H20 -> 0.13833992 | T19: =(I19-I20)/I20 -> -0.043178763 | U19: =(J19-J20)/J20 -> -0.0089871484 | V19: =(D18-D19)/D19 -> 0.061229853 | W19: =(E18-E19)/E19 -> 0.1331805 | X19: =(F19-F23)/F23 -> 0.10666667 | Y19: =(G19-G23)/G23 -> 0.14224138 | Z19: =(H19-H23)/H23 -> 0.33953488 | AA19: =(I19-I23)/I23 -> -0.058366402 | AB19: =(J19-J23)/J23 -> 0.18927955 | AC19: =(D19-D23)/D23 -> 0.18093281 | AD19: =(E19-E23)/E23 -> 0.08311651 | AE19: =(F19-F71)/F71 -> 0.86516854 | AF19: =(G19-G71)/G71 -> 1.1900826 | AG19: =(H19-H71)/H71 -> 1.1818182 | AH19: =(I19-I71)/I71 -> -0.29166667 | AI19: =(J19-J71)/J71 -> 0.64760935 | AJ19: =(D19-D71)/D71 -> 0.85575156 | AK19: =(E19-E71)/E71 -> 0.65130878
A20: =A21+7 -> 46108 | B20: =YEAR(A20) -> 2026 | C20: =MONTH(A20) -> 3 | D20: =0.280558110643*D21 + 0.15041224611*D22 - 0.188812610795*G21 + 0.259276330013*G22 + 0.249001945549*F21 - 0.0911542671384*F22 - 11.8844751787*I21 + 5.64643067713*I22 + 0.185696475006*H21 + 0.247343345212*H22- 3.75210437468 -> 561.9751 | E20: =0.080991528041*E21 + 0.303754553817*E22 - 0.25338201366*G21 + 0.269148503584*G22 + 0.00378757678133*F21 + 0.43547234846*F22 - 12.2555082812*I21 + 15.7710625006*I22 + 0.517281394734*H21 - 0.299449478792*H22 - 3.00478655786 -> 510.99107 | F20: 415 | G20: 625 | H20: 632.5 | I20: 2.976 | J20: 111.27 | K20: =AVERAGE(D20:D23) -> 511.74377 | L20: =AVERAGE(E20:E23) -> 476.49777 | M20: =AVERAGE(F20:F23) -> 395 | N20: =AVERAGE(G20:G23) -> 582.5 | O20: =AVERAGE(H20:H23) -> 603.75 | P20: =AVERAGE(I20:I23) -> 3.05475 | Q20: =(F20-F21)/F21 -> 0 | R20: =(G20-G21)/G21 -> 0.086956522 | S20: =(H20-H21)/H21 -> -0.023166023 | T20: =(I20-I21)/I21 -> -0.032635548 | U20: =(J20-J21)/J21 -> -0.008907099 | V20: =(D20-D21)/D21 -> 0.13530323 | W20: =(E20-E21)/E21 -> 0.098905528 | X20: =(F20-F24)/F24 -> 0.25757576 | Y20: =(G20-G24)/G24 -> 0.30208333 | Z20: =(H20-H24)/H24 -> 0.43261608 | AA20: =(I20-I24)/I24 -> 0.022329097 | AB20: =(J20-J24)/J24 -> 0.52904316 | AC20: =(D20-D24)/D24 -> 0.54388764 | AD20: =(E20-E24)/E24 -> 0.46836515 | AE20: =(F20-F72)/F72 -> 0.82417582 | AF20: =(G20-G72)/G72 -> 1.0661157 | AG20: =(H20-H72)/H72 -> 1.0403226 | AH20: =(I20-I72)/I72 -> -0.24197657 | AI20: =(J20-J72)/J72 -> 0.55098668 | AJ20: =(D20-D72)/D72 -> 0.80699389 | AK20: =(E20-E72)/E72 -> 0.69764475
A21: 46101 | B21: =YEAR(A21) -> 2026 | C21: =MONTH(A21) -> 3 | D21: 495 | E21: 465 | F21: 415 | G21: 575 | H21: 647.5 | I21: 3.0764 | J21: 112.27 | Q21: =(F21-F22)/F22 -> 0.10666667 | R21: =(G21-G22)/G22 -> 0.045454545 | S21: =(H21-H22)/H22 -> 0.083682008 | T21: =(I21-I22)/I22 -> -0.02106536 | U21: =(J21-J22)/J22 -> 0.087887597 | V21: =(D21-D22)/D22 -> 0 | W21: =(E21-E22)/E22 -> 0 | X21: =(F21-F25)/F25 -> 0.25757576 | Y21: =(G21-G25)/G25 -> 0.17948718 | Z21: =(H21-H25)/H25 -> 0.51108518 | AA21: =(I21-I25)/I25 -> 0.0035229645 | AB21: =(J21-J25)/J25 -> 0.56006392 | AC21: =(D21-D25)/D25 -> 0.35989011 | AD21: =(E21-E25)/E25 -> 0.3362069 | AE21: =(F21-F73)/F73 -> 0.72916667 | AF21: =(G21-G73)/G73 -> 0.90082645 | AG21: =(H21-H73)/H73 -> 0.99230769 | AH21: =(I21-I73)/I73 -> -0.24121942 | AI21: =(J21-J73)/J73 -> 0.56492563 | AJ21: =(D21-D73)/D73 -> 0.59163987 | AK21: =(E21-E73)/E73 -> 0.5448505
A22: 46094 | B22: =YEAR(A22) -> 2026 | C22: =MONTH(A22) -> 3 | D22: 495 | E22: 465 | F22: 375 | G22: 550 | H22: 597.5 | I22: 3.1426 | J22: 103.2 | Q22: =(F22-F23)/F23 -> 0 | R22: =(G22-G23)/G23 -> -0.051724138 | S22: =(H22-H23)/H23 -> 0.11162791 | T22: =(I22-I23)/I23 -> 0.039219577 | U22: =(J22-J23)/J23 -> 0.11302847 | V22: =(D22-D23)/D23 -> 0 | W22: =(E22-E23)/E23 -> 0 | X22: =(F22-F26)/F26 -> 0.13636364 | Y22: =(G22-G26)/G26 -> 0.11111111 | Z22: =(H22-H26)/H26 -> 0.48447205 | AA22: =(I22-I26)/I26 -> -0.010017641 | AB22: =(J22-J26)/J26 -> 0.53274915 | AC22: =(D22-D26)/D26 -> 0.35989011 | AD22: =(E22-E26)/E26 -> 0.3362069 | AE22: =(F22-F74)/F74 -> 0.5625 | AF22: =(G22-G74)/G74 -> 0.74603175 | AG22: =(H22-H74)/H74 -> 0.55194805 | AH22: =(I22-I74)/I74 -> -0.26032105 | AI22: =(J22-J74)/J74 -> 0.43849937 | AJ22: =(D22-D74)/D74 -> 0.59163987 | AK22: =(E22-E74)/E74 -> 0.5448505
A23: 46087 | B23: =YEAR(A23) -> 2026 | C23: =MONTH(A23) -> 3 | D23: 495 | E23: 465 | F23: 375 | G23: 580 | H23: 537.5 | I23: 3.024 | J23: 92.72 | Q23: =(F23-F24)/F24 -> 0.13636364 | R23: =(G23-G24)/G24 -> 0.20833333 | S23: =(H23-H24)/H24 -> 0.21744054 | T23: =(I23-I24)/I24 -> 0.038818276 | U23: =(J23-J24)/J24 -> 0.27413393 | V23: =(D23-D24)/D24 -> 0.35989011 | W23: =(E23-E24)/E24 -> 0.3362069 | X23: =(F23-F27)/F27 -> 0.1627907 | Y23: =(G23-G27)/G27 -> 0.1372549 | Z23: =(H23-H27)/H27 -> 0.26470588 | AA23: =(I23-I27)/I27 -> -0.10764873 | AB23: =(J23-J27)/J27 -> 0.3980278 | AC23: =(D23-D27)/D27 -> 0.35989011 | AD23: =(E23-E27)/E27 -> 0.3362069 | AE23: =(F23-F75)/F75 -> 0.57894737 | AF23: =(G23-G75)/G75 -> 0.84126984 | AG23: =(H23-H75)/H75 -> 0.37820513 | AH23: =(I23-I75)/I75 -> -0.30074458 | AI23: =(J23-J75)/J75 -> 0.2924192 | AJ23: =(D23-D75)/D75 -> 0.59163987 | AK23: =(E23-E75)/E75 -> 0.5448505
A24: 46080 | B24: =YEAR(A24) -> 2026 | C24: =MONTH(A24) -> 2 | D24: =AVERAGEIFS(data!G:G,data!A:A,'weekly-forecast'!B24,data!B:B,'weekly-forecast'!C24) -> 364 | E24: =AVERAGEIFS(data!F:F,data!A:A,'weekly-forecast'!B24,data!B:B,'weekly-forecast'!C24) -> 348 | F24: 330 | G24: 480 | H24: 441.5 | I24: 2.911 | J24: 72.771 | K24: =AVERAGE(D24:D27) -> 364 | L24: =AVERAGE(E24:E27) -> 348 | M24: =AVERAGE(F24:F27) -> 328.125 | N24: =AVERAGE(G24:G27) -> 493.125 | O24: =AVERAGE(H24:H27) -> 424.375 | P24: =AVERAGE(I24:I27) -> 3.13495 | Q24: =(F24-F25)/F25 -> 0 | R24: =(G24-G25)/G25 -> -0.015384615 | S24: =(H24-H25)/H25 -> 0.03033839 | T24: =(I24-I25)/I25 -> -0.050430585 | U24: =(J24-J25)/J25 -> 0.011199889 | V24: =(D24-D25)/D25 -> 0 | W24: =(E24-E25)/E25 -> 0 | X24: =(F24-F28)/F28 -> 0.023255814 | Y24: =(G24-G28)/G28 -> -0.076923077 | Z24: =(H24-H28)/H28 -> 0.076829268 | AA24: =(I24-I28)/I28 -> -0.50637591 | AB24: =(J24-J28)/J28 -> 0.12658912 | AC24: =(D24-D28)/D28 -> 0.0083102493 | AD24: =(E24-E28)/E28 -> 0.0057803468 | AE24: =(F24-F76)/F76 -> 0.38947368 | AF24: =(G24-G76)/G76 -> 0.52380952 | AG24: =(H24-H76)/H76 -> 0.13205128 | AH24: =(I24-I76)/I76 -> -0.26645499 | AI24: =(J24-J76)/J76 -> -0.032210445 | AJ24: =(D24-D76)/D76 -> 0.17419355 | AK24: =(E24-E76)/E76 -> 0.12987013
A25: 46073 | B25: =YEAR(A25) -> 2026 | C25: =MONTH(A25) -> 2 | D25: =AVERAGEIFS(data!G:G,data!A:A,'weekly-forecast'!B25,data!B:B,'weekly-forecast'!C25) -> 364 | E25: =AVERAGEIFS(data!F:F,data!A:A,'weekly-forecast'!B25,data!B:B,'weekly-forecast'!C25) -> 348 | F25: 330 | G25: 487.5 | H25: 428.5 | I25: 3.0656 | J25: 71.965 | Q25: =(F25-F26)/F26 -> 0 | R25: =(G25-G26)/G26 -> -0.015151515 | S25: =(H25-H26)/H26 -> 0.064596273 | T25: =(I25-I26)/I26 -> -0.034274194 | U25: =(J25-J26)/J26 -> 0.068840042 | V25: =(D25-D26)/D26 -> 0 | W25: =(E25-E26)/E26 -> 0 | X25: =(F25-F29)/F29 -> 0.18918919 | Y25: =(G25-G29)/G29 -> -0.0625 | Z25: =(H25-H29)/H29 -> 0.11010363 | AA25: =(I25-I29)/I29 -> -0.30970502 | AB25: =(J25-J29)/J29 -> 0.1141112 | AC25: =(D25-D29)/D29 -> 0.0083102493 | AD25: =(E25-E29)/E29 -> 0.0057803468 | AE25: =(F25-F77)/F77 -> 0.38947368 | AF25: =(G25-G77)/G77 -> 0.38297872 | AG25: =(H25-H77)/H77 -> 0.084810127 | AH25: =(I25-I77)/I77 -> -0.26453548 | AI25: =(J25-J77)/J77 -> -0.042929528 | AJ25: =(D25-D77)/D77 -> 0.17419355 | AK25: =(E25-E77)/E77 -> 0.12987013
A26: 46066 | B26: =YEAR(A26) -> 2026 | C26: =MONTH(A26) -> 2 | D26: =AVERAGEIFS(data!G:G,data!A:A,'weekly-forecast'!B26,data!B:B,'weekly-forecast'!C26) -> 364 | E26: =AVERAGEIFS(data!F:F,data!A:A,'weekly-forecast'!B26,data!B:B,'weekly-forecast'!C26) -> 348 | F26: 330 | G26: 495 | H26: 402.5 | I26: 3.1744 | J26: 67.33 | Q26: =(F26-F27)/F27 -> 0.023255814 | R26: =(G26-G27)/G27 -> -0.029411765 | S26: =(H26-H27)/H27 -> -0.052941176 | T26: =(I26-I27)/I27 -> -0.063267233 | U26: =(J26-J27)/J27 -> 0.015198577 | V26: =(D26-D27)/D27 -> 0 | W26: =(E26-E27)/E27 -> 0 | X26: =(F26-F30)/F30 -> 0.18918919 | Y26: =(G26-G30)/G30 -> -0.048076923 | Z26: =(H26-H30)/H30 -> 0.074766355 | AA26: =(I26-I30)/I30 -> -0.018975215 | AB26: =(J26-J30)/J30 -> 0.042355408 | AC26: =(D26-D30)/D30 -> 0.0083102493 | AD26: =(E26-E30)/E30 -> 0.0057803468 | AE26: =(F26-F78)/F78 -> 0.36082474 | AF26: =(G26-G78)/G78 -> 0.40425532 | AG26: =(H26-H78)/H78 -> 0.073333333 | AH26: =(I26-I78)/I78 -> -0.1123539 | AI26: =(J26-J78)/J78 -> -0.1045709 | AJ26: =(D26-D78)/D78 -> 0.17419355 | AK26: =(E26-E78)/E78 -> 0.12987013 | AN26: 46101 | AO26: =AN26+7 -> 46108 | AP26: =AO26+7 -> 46115 | AQ26: =AP26+7 -> 46122 | AR26: =AQ26+7 -> 46129 | AS26: =AR26+7 -> 46136 | AT26: =AS26+7 -> 46143 | AU26: =AT26+7 -> 46150 | AV26: =AU26+7 -> 46157 | ... BB26: =BA26+7 -> 46199
