Workbook

Sheet Input
A1: Date | B1: HDAN | C1: PPAN | D1: Baltic_AN | E1: Ammonia | F1: Urea | G1: Natural_Gas | H1: Brent | I1: Diesel_USD_ton | J1: Urals | K1: FX_rate | M1: Markup_%
A2: 43862 | I2: 638.5 | J2: 48.86 | K2: 2756.95 | M2: 0.0282
A3: 43891 | I3: 625.49 | J3: 15.11 | K3: 2768.95
A4: 43922 | I4: 575.33 | J4: 18.78 | K4: 2783.05
A5: 43952 | I5: 507.62 | J5: 35.46 | K5: 2797.15
A6: 43983 | I6: 446.81 | J6: 44.16 | K6: 2815.65
A7: 44013 | I7: 431.21 | J7: 43.57 | K7: 2835.32
A8: 44044 | I8: 425.64 | J8: 45.1 | K8: 2848.92
A9: 44075 | I9: 422.95 | J9: 40.49 | K9: 2854.13
A10: 44105 | I10: 422.05 | J10: 37.12 | K10: 2853.61
A11: 44136 | I11: 420.59 | J11: 46.92 | K11: 2849.96
A12: 44166 | I12: 421.11 | J12: 50.97 | K12: 2849.53
A13: 44197 | I13: 465.52 | J13: 55.81 | K13: 2849.83
A14: 44228 | I14: 479.92 | J14: 64.92 | K14: 2849.67
... A31: 44743 | I31: 930.5 | J31: 82.81 | K31: 3151.72
A32: 44774 | B32: 500 | C32: 550 | D32: 326.375 | E32: 925 | F32: 511.5 | G32: 8.72 | H32: 97.64 | I32: 955.16 | J32: 78.14 | K32: 3186.09
A33: 44805 | B33: 500 | C33: 530 | D33: 323.1 | E33: 1082.5 | F33: 576.6 | G33: 7.934 | H33: 90.61 | I33: 961.04 | J33: 70.4 | K33: 3252.73
A34: 44835 | B34: 500 | C34: 530 | D34: 380.125 | E34: 1050 | F34: 531.875 | G34: 6.07 | H34: 93.72 | I34: 964.91 | J34: 75.04 | K34: 3369.26
A35: 44866 | B35: 500 | C35: 550 | D35: 390.75 | E35: 1029.375 | F35: 516.25 | G35: 6.3725 | H35: 90.94 | I35: 969.42 | J35: 66.54 | K35: 3406.98
A36: 44896 | B36: 500 | C36: 540 | D36: 388.6 | E36: 894.5 | F36: 491.5 | G36: 5.872 | H36: 81.5 | I36: 977.32 | J36: 56.28 | K36: 3431.8
A37: 44927 | B37: 500 | C37: 550 | D37: 353.75 | E37: 821.25 | F37: 418.75 | G37: 3.52 | H37: 84.08 | I37: 937.02 | J37: 56.05 | K37: 3467.08
A38: 44958 | B38: 500 | C38: 540 | D38: 269.75 | E38: 668.75 | F38: 325 | G38: 2.4225 | H38: 83.63 | I38: 912.19 | J38: 60.27 | K38: 3509.33
A39: 44986 | B39: 460 | C39: 550 | D39: 262.7 | E39: 428.5 | F39: 295 | G39: 2.434 | H39: 79.26 | I39: 890.75 | J39: 58.5 | K39: 3525.27
A40: 45017 | B40: 460 | C40: 550 | D40: 204.75 | E40: 270.625 | F40: 286.25 | G40: 2.1875 | H40: 83.54 | I40: 861.21 | J40: 62.2 | K40: 3496.81
A41: 45047 | B41: 460 | C41: 330 | D41: 175.625 | E41: 241.25 | F41: 295.625 | G41: 2.3 | H41: 75.75 | I41: 831.45 | J41: 53.6 | K41: 3461.07
A42: 45078 | B42: 300 | C42: 330 | D42: 136.5 | E42: 206 | F42: 254.1 | G42: 2.456 | H42: 74.98 | I42: 809.12 | J42: 57.47 | K42: 3439
A43: 45108 | B43: 300 | C43: 330 | D43: 149.375 | E43: 257.5 | F43: 305.75 | G43: 2.635 | H43: 80.11 | I43: 790.14 | J43: 70.23 | K43: 3441.13
... A62: 45689 | B62: 308 | C62: 310 | D62: 240 | E62: 343.125 | F62: 383.75 | G62: 3.765 | H62: 75.19 | I62: 790.75 | J62: 65.49 | K62: 3458.32
A63: 45717 | B63: 301 | C63: 311 | D63: 236.25 | E63: 308.75 | F63: 352.5 | G63: 4.1375 | H63: 71.74 | I63: 788.2 | K63: 3474.07
A64: 45748 | B64: 305 | C64: 315 | D64: 224.375 | E64: 302.5 | F64: 341.25 | G64: 3.4725 | H64: 66.93 | I64: 765.23 | J64: 58.28 | K64: 3542.03
A65: 45778 | B65: 321 | C65: 325 | D65: 214.5 | E65: 302.5 | F65: 351 | G65: 3.438 | H65: 64.09 | I65: 746.85 | J65: 57.95 | K65: 3572.8
A66: 45809 | B66: 308 | C66: 315 | D66: 244.375 | E66: 290 | F66: 382.5 | G66: 3.665 | H66: 69.85 | I66: 729.57 | J66: 63.31 | K66: 3577.56
A67: 45839 | B67: 308 | C67: 320 | D67: 313.75 | E67: 305 | F67: 417.75 | G67: 3.365 | H67: 69.56 | I67: 717.51 | J67: 65.6 | K67: 3584.68
A68: 45870 | B68: 370 | C68: 370 | D68: 308.7 | E68: 323.5 | F68: 443.8 | G68: 2.916 | H68: 67.24 | I68: 713.17 | J68: 65.1 | K68: 3592.14
A69: 45901 | B69: 373 | C69: 391 | D69: 280.625 | E69: 352.5 | F69: 388.625 | G69: 2.9825 | H69: 67.61 | I69: 710.85 | J69: 65.8 | K69: 3593.92
A70: 45931 | B70: 375 | C70: 411 | D70: 245 | E70: 400 | F70: 365.5 | G70: 3.346 | H70: 63.98 | I70: 711.68 | J70: 58.6 | K70: 3592.18
A71: 45962 | B71: 328 | C71: 360 | D71: 247.5 | E71: 448.75 | F71: 367.75 | G71: 4.475 | H71: 63.69 | I71: 714.92 | J71: 55.9 | K71: 3570.73
A72: 45992 | B72: 328 | C72: 360 | D72: 258.75 | E72: 496.875 | F72: 346.25 | G72: 4.43 | H72: 61.81 | I72: 732.76 | J72: 51.3 | K72: 3549.34
A73: 46023 | B73: 346 | C73: 361 | D73: 280.5 | E73: 520 | F73: 378.8 | G73: 4.192 | H73: 64.59 | I73: 826.24 | J73: 55.2 | K73: 3560.74
A74: 46054 | B74: 348 | C74: 364 | D74: 328.125 | E74: 493.125 | F74: 424.375 | G74: 3.135 | H74: 69.5975 | I74: 791.71 | J74: 58.6 | K74: 3565.75
...

Sheet PctChange
A1: Date | B1: HDAN | C1: PPAN | D1: Baltic_AN | E1: Ammonia | F1: Urea | G1: Natural_Gas | H1: Brent | I1: Diesel_USD_ton | J1: Urals | K1: FX_rate
A2: =Input!A2 -> 43862
A3: =Input!A3 -> 43891 | B3: =IFERROR((Input!B3-Input!B2)/Input!B2, "") | C3: =IFERROR((Input!C3-Input!C2)/Input!C2, "") | D3: =IFERROR((Input!D3-Input!D2)/Input!D2, "") | E3: =IFERROR((Input!E3-Input!E2)/Input!E2, "") | F3: =IFERROR((Input!F3-Input!F2)/Input!F2, "") | G3: =IFERROR((Input!G3-Input!G2)/Input!G2, "") | H3: =IFERROR((Input!H3-Input!H2)/Input!H2, "") | I3: =IFERROR((Input!I3-Input!I2)/Input!I2, "") -> -0.020375881 | ... K3: =IFERROR((Input!K3-Input!K2)/Input!K2, "") -> 0.0043526361
A4: =Input!A4 -> 43922 | B4: =IFERROR((Input!B4-Input!B3)/Input!B3, "") | C4: =IFERROR((Input!C4-Input!C3)/Input!C3, "") | D4: =IFERROR((Input!D4-Input!D3)/Input!D3, "") | E4: =IFERROR((Input!E4-Input!E3)/Input!E3, "") | F4: =IFERROR((Input!F4-Input!F3)/Input!F3, "") | G4: =IFERROR((Input!G4-Input!G3)/Input!G3, "") | H4: =IFERROR((Input!H4-Input!H3)/Input!H3, "") | I4: =IFERROR((Input!I4-Input!I3)/Input!I3, "") -> -0.080193129 | ... K4: =IFERROR((Input!K4-Input!K3)/Input!K3, "") -> 0.005092183
A5: =Input!A5 -> 43952 | B5: =IFERROR((Input!B5-Input!B4)/Input!B4, "") | C5: =IFERROR((Input!C5-Input!C4)/Input!C4, "") | D5: =IFERROR((Input!D5-Input!D4)/Input!D4, "") | E5: =IFERROR((Input!E5-Input!E4)/Input!E4, "") | F5: =IFERROR((Input!F5-Input!F4)/Input!F4, "") | G5: =IFERROR((Input!G5-Input!G4)/Input!G4, "") | H5: =IFERROR((Input!H5-Input!H4)/Input!H4, "") | I5: =IFERROR((Input!I5-Input!I4)/Input!I4, "") -> -0.11768898 | ... K5: =IFERROR((Input!K5-Input!K4)/Input!K4, "") -> 0.005066384
A6: =Input!A6 -> 43983 | B6: =IFERROR((Input!B6-Input!B5)/Input!B5, "") | C6: =IFERROR((Input!C6-Input!C5)/Input!C5, "") | D6: =IFERROR((Input!D6-Input!D5)/Input!D5, "") | E6: =IFERROR((Input!E6-Input!E5)/Input!E5, "") | F6: =IFERROR((Input!F6-Input!F5)/Input!F5, "") | G6: =IFERROR((Input!G6-Input!G5)/Input!G5, "") | H6: =IFERROR((Input!H6-Input!H5)/Input!H5, "") | I6: =IFERROR((Input!I6-Input!I5)/Input!I5, "") -> -0.11979433 | ... K6: =IFERROR((Input!K6-Input!K5)/Input!K5, "") -> 0.0066138748
A7: =Input!A7 -> 44013 | B7: =IFERROR((Input!B7-Input!B6)/Input!B6, "") | C7: =IFERROR((Input!C7-Input!C6)/Input!C6, "") | D7: =IFERROR((Input!D7-Input!D6)/Input!D6, "") | E7: =IFERROR((Input!E7-Input!E6)/Input!E6, "") | F7: =IFERROR((Input!F7-Input!F6)/Input!F6, "") | G7: =IFERROR((Input!G7-Input!G6)/Input!G6, "") | H7: =IFERROR((Input!H7-Input!H6)/Input!H6, "") | I7: =IFERROR((Input!I7-Input!I6)/Input!I6, "") -> -0.034914169 | ... K7: =IFERROR((Input!K7-Input!K6)/Input!K6, "") -> 0.0069859535
A8: =Input!A8 -> 44044 | B8: =IFERROR((Input!B8-Input!B7)/Input!B7, "") | C8: =IFERROR((Input!C8-Input!C7)/Input!C7, "") | D8: =IFERROR((Input!D8-Input!D7)/Input!D7, "") | E8: =IFERROR((Input!E8-Input!E7)/Input!E7, "") | F8: =IFERROR((Input!F8-Input!F7)/Input!F7, "") | G8: =IFERROR((Input!G8-Input!G7)/Input!G7, "") | H8: =IFERROR((Input!H8-Input!H7)/Input!H7, "") | I8: =IFERROR((Input!I8-Input!I7)/Input!I7, "") -> -0.01291714 | ... K8: =IFERROR((Input!K8-Input!K7)/Input!K7, "") -> 0.0047966367
A9: =Input!A9 -> 44075 | B9: =IFERROR((Input!B9-Input!B8)/Input!B8, "") | C9: =IFERROR((Input!C9-Input!C8)/Input!C8, "") | D9: =IFERROR((Input!D9-Input!D8)/Input!D8, "") | E9: =IFERROR((Input!E9-Input!E8)/Input!E8, "") | F9: =IFERROR((Input!F9-Input!F8)/Input!F8, "") | G9: =IFERROR((Input!G9-Input!G8)/Input!G8, "") | H9: =IFERROR((Input!H9-Input!H8)/Input!H8, "") | I9: =IFERROR((Input!I9-Input!I8)/Input!I8, "") -> -0.0063198947 | ... K9: =IFERROR((Input!K9-Input!K8)/Input!K8, "") -> 0.0018287632
A10: =Input!A10 -> 44105 | B10: =IFERROR((Input!B10-Input!B9)/Input!B9, "") | C10: =IFERROR((Input!C10-Input!C9)/Input!C9, "") | D10: =IFERROR((Input!D10-Input!D9)/Input!D9, "") | E10: =IFERROR((Input!E10-Input!E9)/Input!E9, "") | F10: =IFERROR((Input!F10-Input!F9)/Input!F9, "") | G10: =IFERROR((Input!G10-Input!G9)/Input!G9, "") | H10: =IFERROR((Input!H10-Input!H9)/Input!H9, "") | I10: =IFERROR((Input!I10-Input!I9)/Input!I9, "") -> -0.0021279111 | ... K10: =IFERROR((Input!K10-Input!K9)/Input!K9, "") -> -0.00018219212
A11: =Input!A11 -> 44136 | B11: =IFERROR((Input!B11-Input!B10)/Input!B10, "") | C11: =IFERROR((Input!C11-Input!C10)/Input!C10, "") | D11: =IFERROR((Input!D11-Input!D10)/Input!D10, "") | E11: =IFERROR((Input!E11-Input!E10)/Input!E10, "") | F11: =IFERROR((Input!F11-Input!F10)/Input!F10, "") | G11: =IFERROR((Input!G11-Input!G10)/Input!G10, "") | H11: =IFERROR((Input!H11-Input!H10)/Input!H10, "") | I11: =IFERROR((Input!I11-Input!I10)/Input!I10, "") -> -0.0034593058 | ... K11: =IFERROR((Input!K11-Input!K10)/Input!K10, "") -> -0.0012790816
A12: =Input!A12 -> 44166 | B12: =IFERROR((Input!B12-Input!B11)/Input!B11, "") | C12: =IFERROR((Input!C12-Input!C11)/Input!C11, "") | D12: =IFERROR((Input!D12-Input!D11)/Input!D11, "") | E12: =IFERROR((Input!E12-Input!E11)/Input!E11, "") | F12: =IFERROR((Input!F12-Input!F11)/Input!F11, "") | G12: =IFERROR((Input!G12-Input!G11)/Input!G11, "") | H12: =IFERROR((Input!H12-Input!H11)/Input!H11, "") | I12: =IFERROR((Input!I12-Input!I11)/Input!I11, "") -> 0.0012363584 | ... K12: =IFERROR((Input!K12-Input!K11)/Input!K11, "") -> -0.00015087931
A13: =Input!A13 -> 44197 | B13: =IFERROR((Input!B13-Input!B12)/Input!B12, "") | C13: =IFERROR((Input!C13-Input!C12)/Input!C12, "") | D13: =IFERROR((Input!D13-Input!D12)/Input!D12, "") | E13: =IFERROR((Input!E13-Input!E12)/Input!E12, "") | F13: =IFERROR((Input!F13-Input!F12)/Input!F12, "") | G13: =IFERROR((Input!G13-Input!G12)/Input!G12, "") | H13: =IFERROR((Input!H13-Input!H12)/Input!H12, "") | I13: =IFERROR((Input!I13-Input!I12)/Input!I12, "") -> 0.10545938 | ... K13: =IFERROR((Input!K13-Input!K12)/Input!K12, "") -> 0.00010528052
A14: =Input!A14 -> 44228 | B14: =IFERROR((Input!B14-Input!B13)/Input!B13, "") | C14: =IFERROR((Input!C14-Input!C13)/Input!C13, "") | D14: =IFERROR((Input!D14-Input!D13)/Input!D13, "") | E14: =IFERROR((Input!E14-Input!E13)/Input!E13, "") | F14: =IFERROR((Input!F14-Input!F13)/Input!F13, "") | G14: =IFERROR((Input!G14-Input!G13)/Input!G13, "") | H14: =IFERROR((Input!H14-Input!H13)/Input!H13, "") | I14: =IFERROR((Input!I14-Input!I13)/Input!I13, "") -> 0.03093315 | ... K14: =IFERROR((Input!K14-Input!K13)/Input!K13, "") -> -5.61437e-05
... A79: =Input!A79 -> 46204 | B79: =IFERROR((Input!B79-Input!B78)/Input!B78, "") -> -0.10842794 | C79: =IFERROR((Input!C79-Input!C78)/Input!C78, "") -> -0.17487564 | D79: =IFERROR((Input!D79-Input!D78)/Input!D78, "") -> -0.05988024 | E79: =IFERROR((Input!E79-Input!E78)/Input!E78, "") -> -0.025316456 | F79: =IFERROR((Input!F79-Input!F78)/Input!F78, "") -> -0.10864882 | G79: =IFERROR((Input!G79-Input!G78)/Input!G78, "") -> 0.011709602 | H79: =IFERROR((Input!H79-Input!H78)/Input!H78, "") -> -0.11213693 | I79: =IFERROR((Input!I79-Input!I78)/Input!I78, "") -> -1 | ... K79: =IFERROR((Input!K79-Input!K78)/Input!K78, "") -> -1

Sheet Regression
A1: Model | B1: coef1 (slope) | C1: coef2 (intercept)
A2: FX (AR1) | D2: {=LINEST(PctChange!K4:K78,PctChange!K3:K77)} -> 0.63375447 | E2: 0.001230801
A3: Diesel-USD (Brent lag2) | D3: {=LINEST(PctChange!I35:I78,PctChange!H33:H76)} -> 0.17033398 | E3: -0.00052964132
A5: VAR: HDAN eq (a11, a12, c1) | D5: {=LINEST(PctChange!B34:B79,J10:K55)} -> 0.54812121 | E5: -0.22937628 | F5: 0.0020286852
A6: VAR: PPAN eq (a21, a22, c2) | D6: {=LINEST(PctChange!C34:C79,J10:K55)} -> 0.12811339 | E6: 0.22452189 | F6: 0.0020980142
J10: =PctChange!B33 -> 0 | K10: =PctChange!C33 -> -0.036363636
J11: =PctChange!B34 -> 0 | K11: =PctChange!C34 -> 0
J12: =PctChange!B35 -> 0 | K12: =PctChange!C35 -> 0.037735849
J13: =PctChange!B36 -> 0 | K13: =PctChange!C36 -> -0.018181818
J14: =PctChange!B37 -> 0 | K14: =PctChange!C37 -> 0.018518519
J15: =PctChange!B38 -> 0 | K15: =PctChange!C38 -> -0.018181818
J16: =PctChange!B39 -> -0.08 | K16: =PctChange!C39 -> 0.018518519
J17: =PctChange!B40 -> 0 | K17: =PctChange!C40 -> 0
J18: =PctChange!B41 -> 0 | K18: =PctChange!C41 -> -0.4
J19: =PctChange!B42 -> -0.34782609 | K19: =PctChange!C42 -> 0
J20: =PctChange!B43 -> 0 | K20: =PctChange!C43 -> 0
J21: =PctChange!B44 -> -0.16666667 | K21: =PctChange!C44 -> -0.15151515
... J55: =PctChange!B78 -> -0.13963959 | K55: =PctChange!C78 -> -0.18692011

Sheet Forecast
A1: Series | B1: Last Actual | C1: Predicted % Change | D1: Forecast
A2: HDAN | B2: =Input!B79 -> 463.165 | C2: =Regression!D5*PctChange!B79+Regression!E5*PctChange!C79+Regression!F5 -> -0.017290643 | D2: =B2*(1+C2) -> 455.15658
A3: PPAN | B3: =Input!C79 -> 475.645 | C3: =Regression!D6*PctChange!B79+Regression!E6*PctChange!C79+Regression!F6 -> -0.051056466 | D3: =B3*(1+C3) -> 451.36025
A4: Diesel_USD_ton | B4: =Input!I78 -> 950.31 | C4: =Regression!D3*PctChange!H77+Regression!E3 -> 4.5505333e-06 | D4: =B4*(1+C4) -> 950.31432
A5: FX_rate | B5: =Input!K78 -> 3576.69 | C5: =Regression!D2*PctChange!K78+Regression!E2 -> 0.0013371329 | D5: =B5*(1+C5) -> 3581.4725
A6: Diesel_MNT (purchasing price) | B6: — | C6: — | D6: =D4*D5*(1+Input!M2) -> 3499504

Sheet Dashboard
A1: Product | B1: Current Value | C1: Next-Month Forecast | D1: 95% Range (approx, ±MAPE) | E1: Backtest MAPE (static, from backend_research/REPORT.md) | F1: MAPE (decimal, static)
A2: HDAN | B2: =Input!B79 -> 463.165 | C2: =Forecast!D2 -> 455.15658 | D2: =TEXT(C2*(1-$F2),"#,##0.0")&" - "&TEXT(C2*(1+$F2),"#,##0.0") -> 412.4 - 497.9 | E2: =F2 -> 0.094 | F2: 0.094
A3: PPAN | B3: =Input!C79 -> 475.645 | C3: =Forecast!D3 -> 451.36025 | D3: =TEXT(C3*(1-$F3),"#,##0.0")&" - "&TEXT(C3*(1+$F3),"#,##0.0") -> 406.2 - 496.5 | E3: =F3 -> 0.1 | F3: 0.1
A4: Diesel-USD | B4: =Input!I78 -> 950.31 | C4: =Forecast!D4 -> 950.31432 | D4: =TEXT(C4*(1-$F4),"#,##0.0")&" - "&TEXT(C4*(1+$F4),"#,##0.0") -> 918.0 - 982.6 | E4: =F4 -> 0.034 | F4: 0.034
A5: FX rate | B5: =Input!K78 -> 3576.69 | C5: =Forecast!D5 -> 3581.4725 | D5: =TEXT(C5*(1-$F5),"#,##0.0")&" - "&TEXT(C5*(1+$F5),"#,##0.0") -> 3,572.5 - 3,590.4 | E5: =F5 -> 0.0025 | F5: 0.0025
A6: Diesel-MNT (purchasing price) | B6: =Input!I78*Input!K78*(1+Input!M2) -> 3494815.1 | C6: =Forecast!D6 -> 3499504 | D6: =TEXT(C6*(1-$F6),"#,##0.0")&" - "&TEXT(C6*(1+$F6),"#,##0.0") -> 3,175,799.9 - 3,823,208.1 | E6: =F6 -> 0.0925 | F6: 0.0925
A8: MAPE values are static, from the 12-month holdout backtest in backend_research/REPORT.md — they do not recalculate as Input grows. The range is an approximate ±MAPE band, not a calibrated statistical interval; see backend_research/REPORT.md's interval-calibration section for why even a proper analytic interval under-covers its stated 95% target on this data.
